Workbook

Sheet Табели
A2: =Ин.яз!B5 -> Адилбеков Бектур
A3: =TODAY() -> 46120 | E3: Пропуски
A4: № | B4: Дисциплина | C4: Сессия | D4: Средний балл | E4: Уваж. | F4: Неуваж.
A5: 1 | B5: Иностранный язык в профессиональной деятельности | D5: =Ин.яз!AN5 -> 3.6 | E5: =Ин.яз!AO5 -> 1 | F5: =Ин.яз!AP5 -> 13
A6: 2 | B6: Физическая культура | D6: =Физ.ра!BL5 -> 4.4 | E6: =Физ.ра!BM5 -> 0 | F6: =Физ.ра!BN5 -> 6
A7: 3 | B7: История | C7: =CONCATENATE(История!AC5) -> 3 | D7: =История!AD5 -> 3.8333333 | E7: =История!AE5 -> 0 | F7: =История!AF5 -> 0
A8: 4 | B8: Проектирование и разработка интерфейсов пользователя | C8: =CONCATENATE(ПиРИП!AP5) | D8: =ПиРИП!AQ5 -> 2.8888889 | E8: =ПиРИП!AR5 -> 0 | F8: =ПиРИП!AS5 -> 10
A9: 5 | B9: Элементы высшей математики | C9: =CONCATENATE('Элемент выш мат'!BQ5) | D9: ='Элемент выш мат'!BR5 -> 3.3333333 | E9: ='Элемент выш мат'!BS5 -> 1 | F9: ='Элемент выш мат'!BT5 -> 10
A10: 6 | B10: Архитектура аппаратных средств | C10: =CONCATENATE('арх.ап.средств'!AP5) | D10: ='арх.ап.средств'!AQ5 -> 5 | E10: ='арх.ап.средств'!AR5 -> 0 | F10: ='арх.ап.средств'!AS5 -> 11
A11: 7 | B11: Операционные системы и среды | C11: =CONCATENATE('Опер.систем-среды'!AV5) | D11: ='Опер.систем-среды'!AW5 -> 2 | E11: ='Опер.систем-среды'!AX5 -> 0 | F11: ='Опер.систем-среды'!AY5 -> 11
A12: 8 | B12: Основы алгоритмизации и программирования | C12: =CONCATENATE('Основы алгоритмизации'!CC5) | D12: ='Основы алгоритмизации'!CD5 -> 2.5 | E12: ='Основы алгоритмизации'!CE5 -> 0 | F12: ='Основы алгоритмизации'!CF5 -> 11
A13: 9 | B13: Основы проектирования баз данных | C13: =CONCATENATE('Осн.пр.Базы данных'!BB5) | D13: ='Осн.пр.Базы данных'!BC5 -> 2.3333333 | E13: ='Осн.пр.Базы данных'!BD5 -> 0 | F13: ='Осн.пр.Базы данных'!BE5 -> 14
A14: 10 | B14: Численные методы | C14: =CONCATENATE('Числ метод'!AI5) -> 2 | D14: ='Числ метод'!AJ5 -> 2.75 | E14: ='Числ метод'!AK5 -> 0 | F14: ='Числ метод'!AL5 -> 2
A15: 11 | B15: Компьютерные сети | C15: =CONCATENATE('Комп сеть'!Y5) -> н | D15: ='Комп сеть'!Z5 -> 3.7857143 | E15: ='Комп сеть'!AA5 -> 0 | F15: ='Комп сеть'!AB5 -> 4
A16: 12 | B16: Теория вероятности и математическая статистика | C16: =CONCATENATE('Теор.вероят и мат.стат'!BX5) | D16: ='Теор.вероят и мат.стат'!BY5 -> 2 | E16: ='Теор.вероят и мат.стат'!BZ5 -> 0 | F16: ='Теор.вероят и мат.стат'!CA5 -> 8
A17: 13 | B17: Дискретная математика | C17: =CONCATENATE('Дискрет.мат '!BQ5) | D17: ='Дискрет.мат '!BR5 -> 2 | E17: ='Дискрет.мат '!BS5 -> 0 | F17: ='Дискрет.мат '!BT5 -> 6
A18: 14 | B18: Разработка программных модулей | C18: =CONCATENATE('Разработка кода ИС'!AO5) | D18: ='Разработка кода ИС'!AP5 -> Нет оценок | E18: ='Разработка кода ИС'!AQ5 -> 0 | F18: ='Разработка кода ИС'!AR5 -> 6
A19: 15 | B19: Внедрение и поддержка компьютерных систем | D19: ='Внедр.подд.комп.систем'!BC5 -> Нет оценок | E19: ='Внедр.подд.комп.систем'!BD5 -> 0 | F19: ='Внедр.подд.комп.систем'!BE5 -> 0
A20: 16 | B20: Обеспечение качества функционирования компьютерных систем | D20: ='Тестирование ИС'!CA5 -> Нет оценок | E20: ='Тестирование ИС'!CB5 -> 0 | F20: ='Тестирование ИС'!CC5 -> 4
A21: 17 | B21: Психология общения | D21: =Псих.общ!BW5 -> Нет оценок | E21: =Псих.общ!BX5 -> 0 | F21: =Псих.общ!BY5 -> 7
A22: 18 | B22: Технология разработки и защиты баз данных | D22: ='Тех.разра.БД'!AA5 -> Нет оценок | E22: ='Тех.разра.БД'!AB5 -> 0 | F22: ='Тех.разра.БД'!AC5 -> 0
A23: 19 | B23: Безопасность жизнедеятельности | D23: =БЖ!AA5 -> 3.6666667 | E23: =БЖ!AB5 -> 0 | F23: =БЖ!AC5 -> 0
A24: 20. | B24: Графический дизайн и мультимедия | C24: ='Граф диз и мульт'!Z6 -> 0 | D24: ='Граф диз и мульт'!AA6 -> 3.3333333 | E24: ='Граф диз и мульт'!AB6 -> 0 | F24: ='Граф диз и мульт'!AC6 -> 6
A25: 21. | B25: Проектирование и дизайн информационных систем | D25: ='Проектирование и дизайн ИС'!AP5 -> 4 | E25: ='Проектирование и дизайн ИС'!AQ5 -> 0 | F25: ='Проектирование и дизайн ИС'!AR5 -> 15
D26: =IFERROR(AVERAGE(D5:D25),"") -> 3.2140377 | E26: =SUM(E5:E25) -> 2 | F26: =SUM(F5:F25) -> 144
E27: Общее количество пропусков
E28: =SUM(E26:F26) -> 146
A30: =Ин.яз!B6 -> Ахметов Артём Рамилевич
A31: =TODAY() -> 46120 | E31: Пропуски
A32: № | B32: Дисциплина | C32: Сессия | D32: Средний балл | E32: Уваж. | F32: Неуваж.
A33: 1 | B33: Иностранный язык в профессиональной деятельности | D33: =Ин.яз!AN6 -> 3.7 | E33: =Ин.яз!AO6 -> 0 | F33: =Ин.яз!AP6 -> 7
A34: 2 | B34: Физическая культура | D34: =Физ.ра!BL6 -> 4 | E34: =Физ.ра!BM6 -> 0 | F34: =Физ.ра!BN6 -> 1
A35: 3 | B35: История | C35: =CONCATENATE(История!AC32) | D35: =История!AD6 -> 3.6666667 | E35: =История!AE32 -> 0 | F35: =История!AF32 -> 0
A36: 4 | B36: Проектирование и разработка интерфейсов пользователя | C36: =CONCATENATE(ПиРИП!AP33) | D36: =ПиРИП!AQ6 -> 4.0833333 | E36: =ПиРИП!AR33 -> 0 | F36: =ПиРИП!AS33 -> 0
A37: 5 | B37: Элементы высшей математики | C37: =CONCATENATE('Элемент выш мат'!BQ32) | D37: ='Элемент выш мат'!BR6 -> 4.125 | E37: ='Элемент выш мат'!BS32 -> 0 | F37: ='Элемент выш мат'!BT32 -> 0
A38: 6 | B38: Архитектура аппаратных средств | C38: =CONCATENATE('арх.ап.средств'!AP31) | D38: ='арх.ап.средств'!AQ6 -> 4.2666667 | E38: ='арх.ап.средств'!AR31 -> 0 | F38: ='арх.ап.средств'!AS31 -> 0
A39: 7 | B39: Операционные системы и среды | C39: =CONCATENATE('Опер.систем-среды'!AV32) | D39: ='Опер.систем-среды'!AW6 -> 3.5 | E39: ='Опер.систем-среды'!AX32 -> 0 | F39: ='Опер.систем-среды'!AY32 -> 0
A40: 8 | B40: Основы алгоритмизации и программирования | C40: =CONCATENATE('Основы алгоритмизации'!CC32) | D40: ='Основы алгоритмизации'!CD6 -> 2.6666667 | E40: ='Основы алгоритмизации'!CE32 -> 0 | F40: ='Основы алгоритмизации'!CF32 -> 0
A41: 9 | B41: Основы проектирования баз данных | C41: =CONCATENATE('Осн.пр.Базы данных'!BB32) | D41: ='Осн.пр.Базы данных'!BC6 -> 3.3333333 | E41: ='Осн.пр.Базы данных'!BD32 -> 0 | F41: ='Осн.пр.Базы данных'!BE32 -> 0
A42: 10 | B42: Численные методы | C42: =CONCATENATE('Числ метод'!AI32) | D42: ='Числ метод'!AJ6 -> 3.6666667 | E42: ='Числ метод'!AK32 -> 0 | F42: ='Числ метод'!AL32 -> 0
...

Sheet История
A1: История
A2: Ляхина Дарья Сергеевна
A3: 9 | B3: 9 | C3: 9 | D3: 9 | E3: 9 | F3: 9 | G3: 9 | H3: 10 | I3: 10 | J3: 10 | K3: 10 | L3: 10 | M3: 10 | O3: 11 | P3: 11 | Q3: 11 | R3: 11 | S3: 11 | T3: 12 | U3: 12 | V3: 12 | W3: 12 | X3: 12 | Y3: 12 | Z3: 12 | AA3: 12 | AB3: 12 | AC3: 3 сем | AE3: Пропуски
A4: 2 | B4: 8 | C4: 12 | D4: 18 | E4: 19 | F4: 23 | G4: 26 | H4: 8 | I4: 15 | J4: 15 | K4: 16 | L4: 24 | M4: 28 | O4: 5 | P4: 5 | Q4: 7 | R4: 20 | S4: 24 | T4: 1 | U4: 2 | V4: 4 | W4: 11 | X4: 13 | Y4: 15 | Z4: 18 | AA4: 19 | AB4: 19 | AC4: ДЗ | AD4: Средний балл | AE4: Уваж. | AF4: Неуваж.
E5: 5 | F5: н/отр | H5: н/отр | I5: 4 | K5: н/отр | L5: н/отр | O5: н/отр | P5: н/отр | Q5: 4 | S5: 4 | W5: 3 | Y5: н/отр | AC5: 3 | AD5: =IFERROR(AVERAGE(A5:AC5),"Нет оценок") -> 3.8333333 | AE5: =COUNTIF(A5:AB5,"н/у") -> 0 | AF5: =COUNTIF(A5:AC5,"н") -> 0
B6: н/отр | E6: 5 | I6: н/у/отр | J6: н/у/отр | K6: оп | L6: 2 | O6: н/отр | P6: н/отр | Q6: 4 | R6: н/отр | S6: 4 | V6: н/отр | W6: н/отр | Y6: 4 | AC6: 3 | AD6: =IFERROR(AVERAGE(A6:AC6),"Нет оценок") -> 3.6666667 | AE6: =COUNTIF(A6:AB6,"н/у") -> 0 | AF6: =COUNTIF(A6:AC6,"н") -> 0
B7: н/отр | E7: 4 | I7: 5 | L7: 5 | N7: + | Q7: 4 | S7: 4 | V7: н/отр | W7: 4 | Y7: 2 | AC7: 3 | AD7: =IFERROR(AVERAGE(A7:AC7),"Нет оценок") -> 3.875 | AE7: =COUNTIF(A7:AB7,"н/у") -> 0 | AF7: =COUNTIF(A7:AC7,"н") -> 0
B8: н/отр | C8: н/отр | D8: н/отр | E8: н/отр | I8: н/отр | J8: н/отр | K8: н/отр | L8: 2 | O8: н/отр | P8: н/отр | Q8: н/отр | S8: 4 | T8: оп | W8: н/отр | Y8: 5 | AA8: н/отр | AB8: н/отр | AC8: 4 | AD8: =IFERROR(AVERAGE(A8:AC8),"Нет оценок") -> 3.75 | AE8: =COUNTIF(A8:AB8,"н/у") -> 0 | AF8: =COUNTIF(A8:AC8,"н") -> 0
C9: оп | E9: 5 | F9: н/отр | I9: н/отр | J9: н/отр | K9: н/отр | L9: н/отр | N9: + | O9: н/отр | P9: н/отр | Q9: 4 | S9: 5 | W9: н/отр | Y9: 4 | AC9: 3 | AD9: =IFERROR(AVERAGE(A9:AC9),"Нет оценок") -> 4.2 | AE9: =COUNTIF(A9:AB9,"н/у") -> 0 | AF9: =COUNTIF(A9:AC9,"н") -> 0
B10: 4 | E10: 5 | I10: 5 | L10: 5 | Q10: 3 | S10: 4 | W10: 4 | Y10: 5 | AC10: 4 | AD10: =IFERROR(AVERAGE(A10:AC10),"Нет оценок") -> 4.3333333 | AE10: =COUNTIF(A10:AB10,"н/у") -> 0 | AF10: =COUNTIF(A10:AC10,"н") -> 0
B11: 5 | C11: н/отр | E11: 5 | G11: н/у/отр | I11: 5 | L11: 3 | O11: н/отр | Q11: 4 | R11: н/у/отр | S11: 5 | W11: 5 | Y11: 5 | Z11: 4 | AC11: 4 | AD11: =IFERROR(AVERAGE(A11:AC11),"Нет оценок") -> 4.5 | AE11: =COUNTIF(A11:AB11,"н/у") -> 0 | AF11: =COUNTIF(A11:AC11,"н") -> 0
A12: н/отр | B12: н/отр | C12: н/отр | D12: н/отр | E12: н/отр | F12: н/отр | I12: 2 | L12: 2 | Q12: 4 | S12: 3 | W12: 4 | Y12: 3 | AC12: 3 | AD12: =IFERROR(AVERAGE(A12:AC12),"Нет оценок") -> 3 | AE12: =COUNTIF(A12:AB12,"н/у") -> 0 | AF12: =COUNTIF(A12:AC12,"н") -> 0
B13: оп | E13: 3 | F13: н/отр | I13: н/отр | J13: н/отр | K13: н/отр | L13: н/отр | O13: н/отр | Q13: н/отр | S13: 3 | W13: 3 | X13: н/отр | Y13: 3 | AC13: 4 | AD13: =IFERROR(AVERAGE(A13:AC13),"Нет оценок") -> 3.2 | AE13: =COUNTIF(A13:AB13,"н/у") -> 0 | AF13: =COUNTIF(A13:AC13,"н") -> 0
B14: 5 | E14: 5 | I14: н/отр | J14: н/отр | K14: н/отр | L14: н/отр | N14: + | Q14: 5 | S14: 4 | W14: 4 | Y14: 4 | AC14: 5 | AD14: =IFERROR(AVERAGE(A14:AC14),"Нет оценок") -> 4.5714286 | AE14: =COUNTIF(A14:AB14,"н/у") -> 0 | AF14: =COUNTIF(A14:AC14,"н") -> 0
E15: 4 | I15: н/отр | J15: н/отр | L15: н/отр | N15: + | O15: н/отр | Q15: 4 | S15: 5 | T15: + | W15: 3 | Y15: 4 | AC15: 4 | AD15: =IFERROR(AVERAGE(A15:AC15),"Нет оценок") -> 4 | AE15: =COUNTIF(A15:AB15,"н/у") -> 0 | AF15: =COUNTIF(A15:AC15,"н") -> 0
E16: 4 | I16: н/отр | J16: н/отр | L16: 2 | Q16: н/отр | R16: н/у/отр | S16: н/у/отр | W16: 4 | Y16: 5 | AC16: 3 | AD16: =IFERROR(AVERAGE(A16:AC16),"Нет оценок") -> 3.6 | AE16: =COUNTIF(A16:AB16,"н/у") -> 0 | AF16: =COUNTIF(A16:AC16,"н") -> 0
B17: оп | C17: н/отр | E17: 5 | G17: н/отр | H17: н/отр | I17: 4 | K17: оп | L17: 2 | M17: н/отр | O17: н/отр | P17: н/отр | Q17: н/отр | R17: н/отр | S17: 4 | T17: оп | U17: н/отр | W17: н/отр | X17: н/отр | Y17: 3 | Z17: н/отр | AC17: 3 | AD17: =IFERROR(AVERAGE(A17:AC17),"Нет оценок") -> 3.5 | AE17: =COUNTIF(A17:AB17,"н/у") -> 0 | AF17: =COUNTIF(A17:AC17,"н") -> 0
E18: 5 | I18: 5 | L18: н/отр | N18: + | Q18: 3 | S18: 4 | W18: 4 | Y18: 5 | AC18: 4 | AD18: =IFERROR(AVERAGE(A18:AC18),"Нет оценок") -> 4.2857143 | AE18: =COUNTIF(A18:AB18,"н/у") -> 0 | AF18: =COUNTIF(A18:AC18,"н") -> 0
B19: н/отр | E19: 4 | G19: н/отр | I19: 4 | K19: н/отр | L19: н/отр | Q19: 4 | S19: 4 | T19: + | W19: н/отр | Y19: 5 | AC19: 3 | AD19: =IFERROR(AVERAGE(A19:AC19),"Нет оценок") -> 4 | AE19: =COUNTIF(A19:AB19,"н/у") -> 0 | AF19: =COUNTIF(A19:AC19,"н") -> 0
C20: н/отр | E20: 5 | I20: 5 | L20: 4 | Q20: 5 | S20: 5 | W20: 5 | Y20: 5 | AC20: 5 | AD20: =IFERROR(AVERAGE(A20:AC20),"Нет оценок") -> 4.875 | AE20: =COUNTIF(A20:AB20,"н/у") -> 0 | AF20: =COUNTIF(A20:AC20,"н") -> 0
E21: 4 | F21: н/отр | I21: 4 | K21: оп | L21: н/отр | Q21: 4 | S21: 4 | W21: н/отр | X21: оп | Y21: 4 | AC21: 3 | AD21: =IFERROR(AVERAGE(A21:AC21),"Нет оценок") -> 3.8333333 | AE21: =COUNTIF(A21:AB21,"н/у") -> 0 | AF21: =COUNTIF(A21:AC21,"н") -> 0
E22: 5 | I22: 3 | J22: н/отр | L22: 5 | N22: + | Q22: 5 | S22: 5 | W22: 5 | Y22: 5 | AC22: 5 | AD22: =IFERROR(AVERAGE(A22:AC22),"Нет оценок") -> 4.75 | AE22: =COUNTIF(A22:AB22,"н/у") -> 0 | AF22: =COUNTIF(A22:AC22,"н") -> 0
C23: оп | E23: н/отр | F23: н/у/отр | G23: н/у/отр | I23: 2 | J23: н/отр | K23: оп | L23: н/отр | N23: + | Q23: 4 | S23: 5 | W23: н/отр | X23: н/отр | Y23: 5 | AA23: н/отр | AB23: н/отр | AC23: 4 | AD23: =IFERROR(AVERAGE(A23:AC23),"Нет оценок") -> 4 | AE23: =COUNTIF(A23:AB23,"н/у") -> 0 | AF23: =COUNTIF(A23:AC23,"н") -> 0
E24: 5 | I24: 5 | L24: 4 | N24: + | Q24: 5 | S24: 4 | V24: н/отр | W24: н/у/отр | X24: н/у/отр | Y24: 5 | AC24: 5 | AD24: =IFERROR(AVERAGE(A24:AC24),"Нет оценок") -> 4.7142857 | AE24: =COUNTIF(A24:AB24,"н/у") -> 0 | AF24: =COUNTIF(A24:AC24,"н") -> 0
E25: 3 | F25: н/отр | G25: н/отр | I25: н/отр | J25: н/отр | L25: н/отр | M25: н/отр | N25: + | Q25: 4 | R25: н/отр | S25: 4 | T25: н/отр | U25: н/отр | V25: н/отр | W25: 2 | X25: н/отр | Y25: 2 | AA25: н/отр | AB25: н/отр | AC25: 3 | AD25: =IFERROR(AVERAGE(A25:AC25),"Нет оценок") -> 3 | AE25: =COUNTIF(A25:AB25,"н/у") -> 0 | AF25: =COUNTIF(A25:AC25,"н") -> 0
AD26: =IFERROR(AVERAGE(A26:AC26),"Нет оценок") -> Нет оценок | AE26: =COUNTIF(A26:AB26,"н/у") -> 0 | AF26: =COUNTIF(A26:AC26,"н") -> 0
E27: 2 | I27: 5 | L27: 2 | M27: н/у/отр | Q27: 2 | S27: 2 | T27: + | W27: 3 | Y27: 5 | AC27: 3 | AD27: =IFERROR(AVERAGE(A27:AC27),"Нет оценок") -> 3 | AE27: =COUNTIF(A27:AB27,"н/у") -> 0 | AF27: =COUNTIF(A27:AC27,"н") -> 0
E28: 3 | I28: н/отр | J28: н/отр | K28: н/отр | L28: н/отр | N28: + | Q28: 5 | S28: 5 | W28: 2 | Y28: 4 | AC28: 4 | AD28: =IFERROR(AVERAGE(A28:AC28),"Нет оценок") -> 3.8333333 | AE28: =COUNTIF(A28:AB28,"н/у") -> 0 | AF28: =COUNTIF(A28:AC28,"н") -> 0
AD29: =IFERROR(AVERAGE(AD5:AD28),"") -> 3.9270186 | AE29: =SUM(AE5:AE28) -> 0 | AF29: =SUM(AF5:AF28) -> 0

Sheet Ин.яз
A1: Наименование предмета | C1: Иностранный язык в профессиональной деятельности
A2: ФИО преподавателя | C2: Скоросова Анна Владимировна
A3: ИСиП 24/2 | B3: Месяц | C3: 9 | D3: 9 | E3: 9 | F3: 10 | G3: 11 | H3: 11 | I3: 11 | J3: 11 | K3: 12 | L3: 12 | M3: 12 | N3: 12 | O3: 12 | P3: 12 | Q3: 12 | R3: 1 | S3: 1 | T3: 1 | U3: 2 | V3: 2 | W3: 2 | X3: 2 | Y3: 3 | Z3: 3 | AO3: Пропуски
B4: Число | C4: 10 | D4: 15 | E4: 23 | F4: 13 | G4: 24 | H4: 25 | I4: 28 | J4: 29 | K4: 2 | L4: 4 | M4: 10 | N4: 12 | O4: 16 | P4: 17 | Q4: 23 | R4: 13 | S4: 17 | T4: 31 | U4: 14 | V4: 16 | W4: 24 | X4: 28 | Y4: 3 | Z4: 4 | AN4: Средний балл | AO4: Уваж. | AP4: Неуваж.
A5: 1. | B5: Адилбеков Бектур | D5: 2 | E5: 5 | F5: 5 | H5: н | I5: н | J5: н | K5: н | L5: н | M5: н | N5: н | O5: н | Q5: н\3 | R5: н | S5: н | T5: н | U5: н/у | V5: н | W5: 2 | X5: + | Y5: н | Z5: 4 | AN5: =IFERROR(AVERAGE(C5:AM5),"Нет оценок") -> 3.6 | AO5: =COUNTIF(C5:AM5,"н/у") -> 1 | AP5: =COUNTIF(C5:AM5,"н") -> 13
A6: 2. | B6: Ахметов Артём Рамилевич | D6: 4 | E6: 5 | F6: н | G6: 5 | H6: 5 | I6: 2 | K6: 4 | L6: 3 | M6: н/отр | N6: н/отр | Q6: 4 | R6: н | S6: 3 | T6: н | V6: 2 | W6: н | X6: н | Y6: н | Z6: н | AN6: =IFERROR(AVERAGE(C6:AM6),"Нет оценок") -> 3.7 | AO6: =COUNTIF(C6:AM6,"н/у") -> 0 | AP6: =COUNTIF(C6:AM6,"н") -> 7
A7: 3. | B7: Бараников Владислав Михайлович | D7: 4 | E7: н/отр | F7: 4 | H7: 2 | I7: 3 | J7: 2 | K7: 4 | L7: н/отр | N7: н/отр | Q7: 4 | R7: 4 | S7: 5 | T7: 4 | U7: н | V7: 3 | W7: 4 | X7: + | Y7: + | Z7: 5 | AN7: =IFERROR(AVERAGE(C7:AM7),"Нет оценок") -> 3.6923077 | AO7: =COUNTIF(C7:AM7,"н/у") -> 0 | AP7: =COUNTIF(C7:AM7,"н") -> 1
A8: 4. | B8: Борсук Артём Дмитриевич | D8: н/отр | E8: н/отр | F8: н/отр | G8: 4 | H8: 2 | I8: 3 | J8: 2 | K8: 4 | L8: 3 | N8: н | Q8: 4 | R8: 5 | S8: н | T8: 4 | U8: н | V8: 3 | W8: н | X8: + | Y8: + | Z8: 4 | AN8: =IFERROR(AVERAGE(C8:AM8),"Нет оценок") -> 3.4545455 | AO8: =COUNTIF(C8:AM8,"н/у") -> 0 | AP8: =COUNTIF(C8:AM8,"н") -> 4
A9: 5. | B9: Гильманов Ильназ Максимович | D9: 3 | E9: н/отр | F9: 4 | G9: 2 | H9: 2 | I9: 3 | J9: 4 | K9: 4 | L9: 3 | N9: н/отр | Q9: 4 | R9: 5 | S9: 4 | T9: 4 | V9: 4 | W9: н | X9: + | Y9: н | Z9: 3 | AN9: =IFERROR(AVERAGE(C9:AM9),"Нет оценок") -> 3.5 | AO9: =COUNTIF(C9:AM9,"н/у") -> 0 | AP9: =COUNTIF(C9:AM9,"н") -> 2
A10: 6. | B10: Говтва Илья Денисович | C10: 5 | D10: 5 | E10: 5 | F10: 5 | G10: 5 | H10: 3 | I10: 2 | J10: 5 | K10: 5 | L10: 5 | M10: 5 | N10: н/отр | Q10: 4 | R10: 5 | S10: 5 | T10: 5 | V10: 5 | W10: 4 | X10: + | Y10: + | Z10: 5 | AN10: =IFERROR(AVERAGE(C10:AM10),"Нет оценок") -> 4.6111111 | AO10: =COUNTIF(C10:AM10,"н/у") -> 0 | AP10: =COUNTIF(C10:AM10,"н") -> 0
A11: 7. | B11: Горшков Владислав Васильевич | D11: 3 | E11: 4 | F11: 4 | H11: 3 | I11: 3 | J11: 2 | K11: 4 | L11: 3 | N11: н/отр | Q11: 4 | R11: 4 | S11: 4 | T11: 4 | V11: 4 | W11: н | X11: + | Y11: + | Z11: 4 | AN11: =IFERROR(AVERAGE(C11:AM11),"Нет оценок") -> 3.5714286 | AO11: =COUNTIF(C11:AM11,"н/у") -> 0 | AP11: =COUNTIF(C11:AM11,"н") -> 1
A12: 8. | B12: Гришко Илья Алексеевич | C12: н/отр | D12: н/отр | E12: н/отр | F12: 3 | H12: 2 | I12: 2 | J12: 2 | K12: 3 | L12: 4 | N12: н | Q12: н\3 | R12: н | S12: 4 | T12: 3 | V12: 4 | X12: + | Y12: н | Z12: 4 | AN12: =IFERROR(AVERAGE(C12:AM12),"Нет оценок") -> 3.1 | AO12: =COUNTIF(C12:AM12,"н/у") -> 0 | AP12: =COUNTIF(C12:AM12,"н") -> 3
A13: 9. | B13: Катков Константин Александрович | C13: 5 | D13: 2 | E13: н | F13: н | H13: н | I13: 2 | J13: н | K13: 2 | L13: 2 | M13: н | N13: н | Q13: н | R13: 2 | S13: н | T13: 2 | V13: н | X13: н | Y13: н | Z13: 2 | AN13: =IFERROR(AVERAGE(C13:AM13),"Нет оценок") -> 2.375 | AO13: =COUNTIF(C13:AM13,"н/у") -> 0 | AP13: =COUNTIF(C13:AM13,"н") -> 11
A14: 10. | B14: Корнеев Андрей Александрович | C14: 5 | D14: 4 | E14: н/отр | F14: н/отр | G14: 4 | H14: 2 | I14: 3 | J14: 4 | K14: 3 | L14: 3 | M14: 2 | N14: 5 | Q14: 4 | R14: 3 | S14: 5 | T14: 4 | V14: 3 | W14: 5 | X14: + | Y14: н | Z14: 3 | AN14: =IFERROR(AVERAGE(C14:AM14),"Нет оценок") -> 3.6470588 | AO14: =COUNTIF(C14:AM14,"н/у") -> 0 | AP14: =COUNTIF(C14:AM14,"н") -> 1
A15: 11. | B15: Макаров Максим Алексеевич | D15: 3 | E15: н/у | F15: 4 | H15: 2 | I15: 2 | K15: 3 | L15: 3 | M15: 5 | N15: н | Q15: 3 | R15: 4 | S15: н | T15: 4 | V15: 3 | X15: + | Y15: н | Z15: 3 | AN15: =IFERROR(AVERAGE(C15:AM15),"Нет оценок") -> 3.25 | AO15: =COUNTIF(C15:AM15,"н/у") -> 1 | AP15: =COUNTIF(C15:AM15,"н") -> 3
A16: 13. | B16: Муллагалиев Вадим Радмилович | C16: 2 | D16: 4 | E16: н/отр | F16: н/отр | G16: н/у/отр | H16: н/у/отр | I16: 2 | J16: 4 | K16: 2 | L16: 3 | N16: н | Q16: 4 | R16: 2 | S16: 5 | T16: 4 | V16: 4 | W16: 4 | X16: + | Y16: н | Z16: 5 | AN16: =IFERROR(AVERAGE(C16:AM16),"Нет оценок") -> 3.4615385 | AO16: =COUNTIF(C16:AM16,"н/у") -> 0 | AP16: =COUNTIF(C16:AM16,"н") -> 2
A17: 12. | B17: Натфуллин Камиль Данисович | C17: н | D17: 3 | E17: н | F17: н | H17: 3 | I17: 4 | J17: 4 | K17: н | L17: 3 | M17: н | N17: н | Q17: н\3 | R17: н/отр | S17: 3 | T17: 4 | V17: н | W17: н | X17: + | Y17: н | Z17: н | AN17: =IFERROR(AVERAGE(C17:AM17),"Нет оценок") -> 3.4285714 | AO17: =COUNTIF(C17:AM17,"н/у") -> 0 | AP17: =COUNTIF(C17:AM17,"н") -> 10
A18: 14. | B18: Носков Ярослав Евгеньевич | D18: 3 | E18: н | F18: 4 | G18: 3 | H18: 2 | I18: 2 | J18: 4 | K18: 4 | L18: 5 | N18: н | Q18: 4 | R18: н | S18: 5 | T18: 4 | V18: 4 | X18: + | Y18: н | Z18: 4 | AN18: =IFERROR(AVERAGE(C18:AM18),"Нет оценок") -> 3.6923077 | AO18: =COUNTIF(C18:AM18,"н/у") -> 0 | AP18: =COUNTIF(C18:AM18,"н") -> 4
A19: 15. | B19: Осыка Владислав Сергеевич | D19: 3 | E19: н/отр | F19: 4 | G19: 2 | H19: 2 | I19: 2 | J19: 2 | K19: 4 | L19: 5 | M19: н/отр | N19: н | Q19: 3 | R19: 5 | S19: 5 | T19: 5 | V19: 4 | W19: 3 | X19: + | Y19: н | Z19: н | AN19: =IFERROR(AVERAGE(C19:AM19),"Нет оценок") -> 3.5 | AO19: =COUNTIF(C19:AM19,"н/у") -> 0 | AP19: =COUNTIF(C19:AM19,"н") -> 3
A20: 16. | B20: Романов Михаил Васильевич | D20: 4 | E20: 5 | F20: 5 | H20: 5 | I20: н/отр | K20: 5 | L20: 5 | M20: н/отр | N20: н/отр | Q20: 4 | R20: 5 | S20: 5 | T20: 5 | V20: 5 | X20: н | Y20: + | Z20: н | AN20: =IFERROR(AVERAGE(C20:AM20),"Нет оценок") -> 4.8181818 | AO20: =COUNTIF(C20:AM20,"н/у") -> 0 | AP20: =COUNTIF(C20:AM20,"н") -> 2
A21: 17. | B21: Руфуллаев Ибрагим Фуадович | C21: 2 | D21: 4 | E21: н/отр | F21: 4 | G21: 3 | H21: 2 | I21: 2 | J21: н/отр | K21: 3 | L21: 4 | M21: н/отр | N21: н | Q21: н\3 | R21: 4 | S21: 4 | T21: 3 | V21: 2 | W21: 3 | X21: + | Y21: н | Z21: 4 | AN21: =IFERROR(AVERAGE(C21:AM21),"Нет оценок") -> 3.1428571 | AO21: =COUNTIF(C21:AM21,"н/у") -> 0 | AP21: =COUNTIF(C21:AM21,"н") -> 2
A22: 18. | B22: Сарычев Данила Андреевич | C22: 5 | D22: 4 | E22: н/отр | F22: 4 | G22: 4 | H22: 4 | I22: 3 | J22: 5 | K22: 3 | L22: 5 | N22: н/отр | Q22: н\3 | R22: 5 | S22: 4 | T22: н | U22: н | V22: 4 | W22: н | X22: + | Y22: + | Z22: 4 | AN22: =IFERROR(AVERAGE(C22:AM22),"Нет оценок") -> 4.1538462 | AO22: =COUNTIF(C22:AM22,"н/у") -> 0 | AP22: =COUNTIF(C22:AM22,"н") -> 3
A23: 19. | B23: Сурков Кирилл Александрович | C23: 5 | D23: 5 | E23: н/у/отр | F23: н/отр | G23: 5 | H23: 4 | I23: н | J23: 5 | K23: 5 | L23: н/отр | M23: н | N23: н | O23: н | Q23: 4 | R23: н | S23: н | T23: 4 | U23: н | V23: 5 | W23: н | X23: н | Y23: н | Z23: 5 | AN23: =IFERROR(AVERAGE(C23:AM23),"Нет оценок") -> 4.7 | AO23: =COUNTIF(C23:AM23,"н/у") -> 0 | AP23: =COUNTIF(C23:AM23,"н") -> 10
A24: 20. | B24: Усатов Тимофей Анатольевич | D24: 3 | E24: 4 | F24: 5 | H24: 2 | I24: 2 | J24: 4 | K24: 5 | L24: н/отр | M24: н/у/отр | N24: н/отр | Q24: 4 | R24: 4 | S24: 5 | T24: 4 | V24: 4 | W24: 3 | X24: + | Y24: н/отр | Z24: 5 | AN24: =IFERROR(AVERAGE(C24:AM24),"Нет оценок") -> 3.8571429 | AO24: =COUNTIF(C24:AM24,"н/у") -> 0 | AP24: =COUNTIF(C24:AM24,"н") -> 0
A25: 21. | B25: Халитов Кирилл Родионович | D25: н | E25: н | F25: н | H25: н | I25: 4 | J25: н | K25: н/у | L25: н/у | M25: н | N25: н | O25: н | Q25: н\3 | R25: н | S25: н | T25: н | U25: н | V25: н | X25: + | Y25: н | Z25: 4 | AN25: =IFERROR(AVERAGE(C25:AM25),"Нет оценок") -> 4 | AO25: =COUNTIF(C25:AM25,"н/у") -> 2 | AP25: =COUNTIF(C25:AM25,"н") -> 14
A26: 21. | B26: Хорошилов Игорь Александрович | AN26: =IFERROR(AVERAGE(C26:AM26),"Нет оценок") -> Нет оценок | AO26: =COUNTIF(C26:AM26,"н/у") -> 0 | AP26: =COUNTIF(C26:AM26,"н") -> 0
A27: 22. | B27: Хрычев Мирон Евгеньевич | D27: 4 | E27: н | F27: 4 | G27: 2 | H27: 2 | I27: 4 | J27: н | K27: 2 | L27: 3 | N27: н | Q27: 4 | R27: н | S27: 4 | T27: 4 | V27: 3 | X27: 2 | Y27: н | Z27: н | AN27: =IFERROR(AVERAGE(C27:AM27),"Нет оценок") -> 3.1666667 | AO27: =COUNTIF(C27:AM27,"н/у") -> 0 | AP27: =COUNTIF(C27:AM27,"н") -> 6
A28: 23. | B28: Цапов Илья Валерьевич | D28: 4 | E28: н/отр | F28: н/у/отр | G28: н/отр | H28: н/отр | I28: 3 | J28: н/отр | K28: 5 | L28: н | M28: н/отр | N28: н | Q28: 4 | R28: н | S28: н | T28: 4 | U28: н | V28: 5 | W28: 2 | X28: + | Y28: н | Z28: 3 | AN28: =IFERROR(AVERAGE(C28:AM28),"Нет оценок") -> 3.75 | AO28: =COUNTIF(C28:AM28,"н/у") -> 0 | AP28: =COUNTIF(C28:AM28,"н") -> 6
A29: Дата | B29: Тема / ДЗ | AN29: =IFERROR(AVERAGE(AN5:AN28),"") -> 3.6596767 | AO29: =SUM(AO5:AO28) -> 4 | AP29: =SUM(AP5:AP28) -> 108
A30: 10\09 | B30: Biligual people. Question word order
A31: 15\09 | B31: Formal\informal letters.
A32: 23\09 | B32: Видеолекция. Computers. ex 1-8 | P32: - | Q32: к\р
A33: 13\10 | B33: Задание на moodle
A34: 24\11 | B34: Relationship. Present and past Tenses
A35: 25\11 | B35: Relationship. Present and past Tenses зачет\отработка
A36: 28\11 | B36: p. Present and past Tenses test
A37: 29\11 | B37: Reading telecoms trends
A38: 2\12 | B38: History of computers hardware
A39: 4\12 | B39: Computers and IT in the modern world
A40: 10\12 | B40: Information technologies in Russia and the world
...

Sheet ПиРИП
A1: Наименование предмета | C1: Проектирование и разработка интерфейсов пользователя
A2: ФИО преподавателя | C2: Коваленко Даниил Романович
A3: ИСиП 24/2 | B3: Месяц | C3: Сентябрь | G3: Октябрь | J3: Ноябрь | M3: Декабрь | Z3: Январь | AD3: Февраль | AG3: М | AH3: Апрель | AR3: Пропуски
B4: Число | C4: 2 | D4: 5 | F4: 26 | G4: 28 | I4: 29 | J4: 6 | K4: 7 | L4: КЛ | M4: 5 | N4: 6 | O4: 6 | P4: 8 | Q4: 8 | R4: 10 | S4: 11 | T4: 16 | U4: 17 | V4: 17 | W4: 22 | X4: 23 | Y4: 23 | Z4: 16 | AA4: 21 | AB4: 23 | AC4: 30 | AD4: 4 | AE4: 7 | AF4: 7 | AG4: 11 | AH4: 1 | AI4: 6 | AQ4: Средний балл | AR4: Уваж. | AS4: Неуваж.
A5: 1. | B5: Адилбеков Бектур | D5: 4 | F5: н | G5: \1 | I5: н | L5: 2 | M5: 3 | N5: 3 | O5: 3 | P5: 3 | Q5: 3 | R5: 3 | U5: н | V5: н | W5: н | X5: н | AA5: н | AB5: н | AG5: н | AH5: 2 | AI5: н | AQ5: =IFERROR(AVERAGE(C5:AP5),"Нет оценок") -> 2.8888889 | AR5: =COUNTIF(C5:AO5,"н/у") -> 0 | AS5: =COUNTIF(C5:AP5,"н") -> 10
A6: 2. | B6: Ахметов Артём Рамилевич | D6: 4 | G6: \2 | H6: 5 | L6: 5 | M6: 5 | N6: 3 | O6: 3 | P6: 3 | Q6: 3 | R6: 3 | U6: н | V6: н | X6: н | Z6: н | AB6: н | AC6: н | AD6: н | AE6: н | AF6: н | AG6: 5 | AH6: 5 | AI6: 5 | AQ6: =IFERROR(AVERAGE(C6:AP6),"Нет оценок") -> 4.0833333 | AR6: =COUNTIF(C6:AO6,"н/у") -> 0 | AS6: =COUNTIF(C6:AP6,"н") -> 9
A7: 3. | B7: Бараников Владислав Михайлович | C7: 5 | D7: 4 | E7: 5 | F7: 5 | G7: \3 | H7: 5 | L7: 4 | M7: 5 | N7: 4 | O7: 4 | P7: 5 | Q7: 5 | R7: 5 | T7: 4 | W7: 4 | Z7: 4 | AA7: 4 | AG7: 5 | AH7: 4 | AI7: 2 | AQ7: =IFERROR(AVERAGE(C7:AP7),"Нет оценок") -> 4.3684211 | AR7: =COUNTIF(C7:AO7,"н/у") -> 0 | AS7: =COUNTIF(C7:AP7,"н") -> 0
A8: 4. | B8: Борсук Артём Дмитриевич | C8: 5 | D8: 4 | G8: \4 | H8: 4 | L8: 5 | M8: 5 | N8: 3 | O8: 3 | P8: 3 | Q8: 3 | R8: 3 | W8: н | X8: н | Z8: н | AA8: н | AE8: н | AF8: н | AG8: 5 | AH8: 5 | AI8: 2 | AQ8: =IFERROR(AVERAGE(C8:AP8),"Нет оценок") -> 3.8461538 | AR8: =COUNTIF(C8:AO8,"н/у") -> 0 | AS8: =COUNTIF(C8:AP8,"н") -> 6
A9: 5. | B9: Гильманов Ильназ Максимович | D9: 5 | E9: 5 | F9: - | G9: \5 | H9: 5 | I9: 3 | L9: 3 | M9: 5 | N9: 4 | O9: 4 | P9: 3 | Q9: 3 | R9: 3 | T9: 5 | W9: н | AE9: н | AF9: н | AG9: 2 | AH9: 2 | AI9: 2 | AQ9: =IFERROR(AVERAGE(C9:AP9),"Нет оценок") -> 3.6 | AR9: =COUNTIF(C9:AO9,"н/у") -> 0 | AS9: =COUNTIF(C9:AP9,"н") -> 3
A10: 6. | B10: Говтва Илья Денисович | C10: 5 | D10: 5 | E10: 5 | F10: 5 | G10: \6 | H10: 5 | L10: 5 | M10: 5 | N10: 4 | O10: 4 | P10: 5 | Q10: 5 | R10: 5 | S10: 5 | T10: 5 | U10: 5 | V10: 5 | W10: 5 | Z10: 5 | AA10: 5 | AB10: 5 | AC10: 5 | AD10: 5 | AG10: 5 | AH10: 5 | AI10: 5 | AQ10: =IFERROR(AVERAGE(C10:AP10),"Нет оценок") -> 4.92 | AR10: =COUNTIF(C10:AO10,"н/у") -> 0 | AS10: =COUNTIF(C10:AP10,"н") -> 0
A11: 7. | B11: Горшков Владислав Васильевич | D11: 4 | F11: 3 | G11: \7 | H11: 5 | L11: 4 | M11: 5 | N11: 3 | O11: 3 | P11: 3 | Q11: 3 | R11: 3 | T11: 4 | X11: н | Z11: н | AE11: н | AF11: н | AG11: 5 | AH11: 3 | AI11: 2 | AQ11: =IFERROR(AVERAGE(C11:AP11),"Нет оценок") -> 3.5714286 | AR11: =COUNTIF(C11:AO11,"н/у") -> 0 | AS11: =COUNTIF(C11:AP11,"н") -> 4
A12: 8. | B12: Гришко Илья Алексеевич | D12: 2 | F12: - | G12: \8 | L12: 3 | M12: 5 | N12: 3 | O12: 3 | P12: 4 | Q12: 3 | R12: 4 | S12: 4 | T12: - | U12: 3 | V12: 4 | W12: 4 | Z12: 4 | AA12: 4 | AB12: 3 | AC12: 4 | AD12: 3 | AG12: 2 | AH12: 2 | AI12: 2 | AQ12: =IFERROR(AVERAGE(C12:AP12),"Нет оценок") -> 3.3 | AR12: =COUNTIF(C12:AO12,"н/у") -> 0 | AS12: =COUNTIF(C12:AP12,"н") -> 0
A13: 9. | B13: Катков Константин Александрович | C13: 5 | D13: 2 | F13: 2 | G13: \9 | H13: 5 | I13: н | L13: 5 | M13: н | N13: 2 | O13: 2 | P13: н | Q13: н | S13: н | T13: н | V13: н | X13: н | Z13: н | AA13: н | AE13: н | AF13: н | AG13: 2 | AH13: н | AI13: 2 | AQ13: =IFERROR(AVERAGE(C13:AP13),"Нет оценок") -> 3 | AR13: =COUNTIF(C13:AO13,"н/у") -> 0 | AS13: =COUNTIF(C13:AP13,"н") -> 13
A14: 10. | B14: Корнеев Андрей Александрович | D14: 2 | E14: 5 | F14: - | G14: \10 | H14: 5 | L14: 3 | M14: 5 | N14: 3 | O14: 3 | P14: 3 | Q14: 3 | R14: 3 | T14: - | AG14: 2 | AH14: 2 | AI14: 2 | AQ14: =IFERROR(AVERAGE(C14:AP14),"Нет оценок") -> 3.1538462 | AR14: =COUNTIF(C14:AO14,"н/у") -> 0 | AS14: =COUNTIF(C14:AP14,"н") -> 0
A15: 11. | B15: Макаров Максим Алексеевич | C15: 5 | D15: 3 | E15: 3 | F15: - | G15: \11 | H15: 5 | L15: 5 | M15: 5 | N15: 4 | O15: 4 | P15: 5 | Q15: 5 | R15: 5 | T15: 5 | X15: н | AG15: 5 | AH15: 5 | AI15: 5 | AQ15: =IFERROR(AVERAGE(C15:AP15),"Нет оценок") -> 4.6 | AR15: =COUNTIF(C15:AO15,"н/у") -> 0 | AS15: =COUNTIF(C15:AP15,"н") -> 1
A16: 13. | B16: Муллагалиев Вадим Радмилович | D16: 3 | F16: 5 | G16: \12 | H16: 5 | L16: 5 | M16: 2 | N16: 5 | O16: 4 | P16: 5 | Q16: 5 | R16: 5 | T16: 5 | W16: 4 | X16: н | Z16: 4 | AA16: 4 | AD16: н | AG16: 5 | AH16: 5 | AI16: 2 | AQ16: =IFERROR(AVERAGE(C16:AP16),"Нет оценок") -> 4.2941176 | AR16: =COUNTIF(C16:AO16,"н/у") -> 0 | AS16: =COUNTIF(C16:AP16,"н") -> 2
A17: 12. | B17: Натфуллин Камиль Данисович | D17: 4 | F17: н | G17: \13 | H17: н | I17: н | L17: 4 | M17: н | N17: 3 | O17: 3 | P17: н | Q17: н | S17: н | U17: н | V17: н | W17: н | X17: н | Z17: н | AG17: н | AH17: 2 | AI17: н | AQ17: =IFERROR(AVERAGE(C17:AP17),"Нет оценок") -> 3.2 | AR17: =COUNTIF(C17:AO17,"н/у") -> 0 | AS17: =COUNTIF(C17:AP17,"н") -> 14
A18: 14. | B18: Носков Ярослав Евгеньевич | D18: 5 | E18: 5 | F18: 5 | G18: \14 | H18: 5 | I18: н | L18: 4 | M18: 5 | N18: 3 | O18: 3 | P18: 5 | Q18: 5 | R18: 5 | T18: - | X18: н | AB18: н | AG18: 5 | AH18: 5 | AI18: 2 | AQ18: =IFERROR(AVERAGE(C18:AP18),"Нет оценок") -> 4.4285714 | AR18: =COUNTIF(C18:AO18,"н/у") -> 0 | AS18: =COUNTIF(C18:AP18,"н") -> 3
A19: 15. | B19: Осыка Владислав Сергеевич | D19: 5 | E19: 5 | F19: 4 | G19: \15 | H19: 4 | L19: 3 | M19: 5 | N19: 4 | O19: 4 | P19: 5 | Q19: 5 | R19: 4 | S19: 4 | T19: 4 | U19: 4 | V19: 4 | W19: 4 | Z19: 4 | AA19: 4 | AC19: н | AG19: 5 | AH19: 5 | AI19: 5 | AQ19: =IFERROR(AVERAGE(C19:AP19),"Нет оценок") -> 4.3333333 | AR19: =COUNTIF(C19:AO19,"н/у") -> 0 | AS19: =COUNTIF(C19:AP19,"н") -> 1
A20: 16. | B20: Романов Михаил Васильевич | D20: 5 | E20: 5 | F20: 5 | G20: \16 | H20: 5 | L20: 4 | M20: 5 | N20: 4 | O20: 4 | P20: 3 | Q20: 3 | R20: 3 | U20: н | V20: н | AD20: н | AG20: 2 | AH20: 2 | AI20: 2 | AQ20: =IFERROR(AVERAGE(C20:AP20),"Нет оценок") -> 3.7142857 | AR20: =COUNTIF(C20:AO20,"н/у") -> 0 | AS20: =COUNTIF(C20:AP20,"н") -> 3
A21: 17. | B21: Руфуллаев Ибрагим Фуадович | C21: 5 | D21: 5 | E21: 5 | F21: 5 | G21: \17 | H21: 5 | L21: 4 | M21: 5 | N21: 3 | O21: 3 | P21: 4 | Q21: 5 | R21: 5 | T21: - | Z21: н | AA21: н | AB21: н | AG21: 2 | AH21: н | AI21: 2 | AQ21: =IFERROR(AVERAGE(C21:AP21),"Нет оценок") -> 4.1428571 | AR21: =COUNTIF(C21:AO21,"н/у") -> 0 | AS21: =COUNTIF(C21:AP21,"н") -> 4
A22: 18. | B22: Сарычев Данила Андреевич | F22: 5 | G22: \18 | H22: 5 | L22: 5 | M22: 5 | N22: 5 | O22: 5 | P22: 5 | Q22: 5 | R22: 5 | S22: 5 | T22: 5 | U22: 5 | V22: 5 | W22: 5 | Z22: 5 | AA22: 5 | AB22: 5 | AC22: 5 | AD22: 5 | AG22: 5 | AH22: 5 | AI22: 5 | AQ22: =IFERROR(AVERAGE(C22:AP22),"Нет оценок") -> 5 | AR22: =COUNTIF(C22:AO22,"н/у") -> 0 | AS22: =COUNTIF(C22:AP22,"н") -> 0
A23: 19. | B23: Сурков Кирилл Александрович | C23: 5 | D23: 5 | E23: 5 | G23: \19 | H23: 5 | L23: 5 | M23: 4 | N23: 5 | O23: 5 | P23: 5 | Q23: 5 | R23: 5 | S23: 5 | U23: 5 | V23: 5 | W23: н | X23: н | Z23: н | AA23: н | AB23: н | AC23: н | AD23: н | AG23: н | AH23: 2 | AI23: н | AQ23: =IFERROR(AVERAGE(C23:AP23),"Нет оценок") -> 4.7333333 | AR23: =COUNTIF(C23:AO23,"н/у") -> 0 | AS23: =COUNTIF(C23:AP23,"н") -> 9
A24: 20. | B24: Усатов Тимофей Анатольевич | D24: 5 | E24: 5 | F24: 5 | G24: \20 | H24: 5 | L24: 5 | M24: 5 | N24: 4 | O24: 4 | P24: 5 | Q24: 5 | R24: 5 | S24: 5 | T24: - | U24: 5 | V24: 5 | W24: 5 | Z24: 5 | AA24: 5 | AB24: 5 | AC24: 5 | AD24: 5 | AG24: 5 | AH24: 5 | AI24: 5 | AQ24: =IFERROR(AVERAGE(C24:AP24),"Нет оценок") -> 4.9130435 | AR24: =COUNTIF(C24:AO24,"н/у") -> 0 | AS24: =COUNTIF(C24:AP24,"н") -> 0
A25: 21. | B25: Халитов Кирилл Родионович | D25: 4 | F25: н/у | G25: \1 | H25: н | I25: н | L25: 5 | M25: н | N25: 3 | O25: 3 | P25: н/у | Q25: н/у | R25: н | T25: н | U25: н | V25: н | W25: н | X25: н | Z25: н | AA25: н | AB25: н | AC25: н | AD25: н | AE25: н | AF25: н | AG25: 5 | AH25: 4 | AI25: н | AQ25: =IFERROR(AVERAGE(C25:AP25),"Нет оценок") -> 4 | AR25: =COUNTIF(C25:AO25,"н/у") -> 3 | AS25: =COUNTIF(C25:AP25,"н") -> 17
A26: 21. | B26: Хорошилов Игорь Александрович | AQ26: =IFERROR(AVERAGE(C26:AP26),"Нет оценок") -> Нет оценок | AR26: =COUNTIF(C26:AO26,"н/у") -> 0 | AS26: =COUNTIF(C26:AP26,"н") -> 0
A27: 22. | B27: Хрычёв Мирон Евгеньевич | D27: 2 | G27: \3 | H27: н/у | I27: н/у | L27: 2 | M27: н | N27: 3 | O27: 3 | P27: 4 | Q27: 3 | R27: 3 | T27: - | W27: 4 | X27: н | Z27: 4 | AA27: 4 | AB27: н | AG27: 5 | AH27: 5 | AI27: 5 | AQ27: =IFERROR(AVERAGE(C27:AP27),"Нет оценок") -> 3.6153846 | AR27: =COUNTIF(C27:AO27,"н/у") -> 2 | AS27: =COUNTIF(C27:AP27,"н") -> 3
A28: 23. | B28: Цапов Илья Валерьевич | D28: 3 | E28: 5 | G28: \4 | H28: 5 | L28: 5 | M28: 2 | N28: 5 | O28: 5 | P28: 5 | Q28: 5 | R28: 5 | S28: н | T28: 5 | X28: н | Z28: н | AA28: н | AB28: н | AC28: н | AG28: 2 | AH28: 2 | AI28: 2 | AQ28: =IFERROR(AVERAGE(C28:AP28),"Нет оценок") -> 4 | AR28: =COUNTIF(C28:AO28,"н/у") -> 0 | AS28: =COUNTIF(C28:AP28,"н") -> 6
N29: ПР 1 | O29: ПР 1 | P29: ПР 2 | Q29: ПР 2 | R29: ПР 2 | S29: ПР 3 | U29: ПР 3 | V29: ПР 3 | W29: ПР 4 | X29: ПР 4 | Z29: ПР 4 | AA29: ПР 4 | AB29: ПР 5 | AC29: ПР 5 | AD29: ПР 5 | AG29: Дневник | AH29: Дневник | AI29: Дневник | AQ29: =IFERROR(AVERAGE(AQ6:AQ28),"") -> 4.0371868 | AR29: =SUM(AR6:AR28) -> 5 | AS29: =SUM(AS6:AS28) -> 98
A30: Дата | B30: Тема / ДЗ
A31: 45902 | B31: 1.1. Категории пользовательских интерфейсов информационных систем (1-9 слайды) + Задание
A32: 45905 | B32: 1.1. Категории пользовательских интерфейсов информационных систем (9-15 слайды) + Задание
A33: 45926 | B33: 1.2. Элементы опыта взаимодействия в системе человек-компьютер (1-6 слайды) + Задание
A34: 45958 | B34: Задание по проектированию 1
A35: 45959 | B35: Задание по проектированию 2
A36: 45967 | B36: Подготовкак к коллоквиуму, письменные ответы на вопросы
A37: 45996 | B37: 2.1. Основы WEB дизайна
A38: 45997 | B38: Практическая работа 1 - html
A39: 45997 | B39: Практическая работа 1 - html
A40: 45999 | B40: Практическая работа 2 - html
...

Sheet Физ.ра
A1: Наименование предмета | C1: Физическая культура
A2: ФИО преподавателя | C2: Патраков Андрей Иванович
A3: ИСиП 24/2 | B3: Месяц | C3: группа | D3: сен | E3: сен | F3: сен | G3: окт | H3: окт | I3: окт | J3: окт | K3: окт | L3: ноя | M3: ноя | N3: ноя | O3: дек | P3: дек | Q3: дек | T3: фев | U3: фев | V3: фев | W3: март | BJ3: 3 сем | BK3: 4 сем | BM3: Пропуски
B4: Число | C4: здоровья | D4: 3 | E4: 9 | F4: 23 | G4: 15 | H4: 24 | I4: 29 | J4: 29 | K4: 31 | L4: 5 | M4: 12 | N4: 21 | O4: 3 | P4: 12 | Q4: 12 | R4: 19 | T4: 18 | U4: 21 | V4: 21 | W4: 10 | BJ4: З | BK4: З | BL4: Средний балл | BM4: Уваж. | BN4: Неуваж.
A5: 1. | B5: Адилбеков Бектур | C5: осн | E5: 5 | F5: 5 | G5: н/отр | H5: 3 | I5: 5 | J5: 5 | K5: 5 | L5: н/отр | M5: 5 | N5: н | O5: н | P5: 3 | Q5: 5 | R5: н | T5: 3 | U5: н | V5: н | W5: н | BJ5: неявка | BL5: =IFERROR(AVERAGE(C5:BK5),"Нет оценок") -> 4.4 | BM5: =COUNTIF(C5:BK5,"н/у") -> 0 | BN5: =COUNTIF(C5:BK5,"н") -> 6
A6: 2. | B6: Ахметов Артём Рамилевич | C6: подг | E6: 5 | F6: 5 | G6: н/отр | H6: н/отр | I6: н/отр | J6: н/отр | K6: 3 | L6: н/отр | M6: 5 | N6: 3 | O6: 3 | P6: 3 | Q6: 3 | R6: 5 | T6: н | U6: 5 | V6: 5 | W6: 3 | BJ6: зачтено | BL6: =IFERROR(AVERAGE(C6:BK6),"Нет оценок") -> 4 | BM6: =COUNTIF(C6:BK6,"н/у") -> 0 | BN6: =COUNTIF(C6:BK6,"н") -> 1
A7: 3. | B7: Бараников Владислав Михайлович | C7: осн | E7: 5 | F7: 5 | G7: 5 | H7: 5 | I7: 5 | J7: 5 | K7: 5 | L7: 5 | M7: 5 | N7: 5 | O7: 5 | P7: 5 | Q7: 5 | R7: 5 | T7: 5 | U7: 5 | V7: 5 | W7: 5 | BJ7: зачтено | BL7: =IFERROR(AVERAGE(C7:BK7),"Нет оценок") -> 5 | BM7: =COUNTIF(C7:BK7,"н/у") -> 0 | BN7: =COUNTIF(C7:BK7,"н") -> 0
A8: 4. | B8: Борсук Артём Дмитриевич | C8: осн | E8: 3 | F8: 3 | G8: 5 | H8: н/отр | I8: 3 | J8: 5 | K8: 5 | L8: 5 | M8: 5 | N8: 5 | O8: 5 | P8: 5 | Q8: 5 | T8: 5 | U8: 5 | V8: 5 | W8: н | BJ8: зачтено | BL8: =IFERROR(AVERAGE(C8:BK8),"Нет оценок") -> 4.6 | BM8: =COUNTIF(C8:BK8,"н/у") -> 0 | BN8: =COUNTIF(C8:BK8,"н") -> 1
A9: 5. | B9: Гильманов Ильназ Максимович | C9: осн | E9: н/отр | F9: 3 | G9: 5 | H9: 5 | I9: 5 | J9: 5 | K9: 5 | L9: 5 | M9: 5 | N9: 5 | O9: 5 | P9: 5 | Q9: 5 | R9: 5 | T9: 5 | U9: 5 | V9: 5 | W9: н | BJ9: зачтено | BL9: =IFERROR(AVERAGE(C9:BK9),"Нет оценок") -> 4.875 | BM9: =COUNTIF(C9:BK9,"н/у") -> 0 | BN9: =COUNTIF(C9:BK9,"н") -> 1
A10: 6. | B10: Говтва Илья Денисович | C10: осн | E10: 5 | F10: 5 | G10: 5 | H10: 5 | I10: 5 | J10: 5 | K10: 5 | L10: 5 | M10: 5 | N10: 5 | O10: 5 | P10: 5 | Q10: 5 | R10: 5 | T10: 5 | U10: 5 | V10: 5 | W10: 5 | BJ10: зачтено | BL10: =IFERROR(AVERAGE(C10:BK10),"Нет оценок") -> 5 | BM10: =COUNTIF(C10:BK10,"н/у") -> 0 | BN10: =COUNTIF(C10:BK10,"н") -> 0
A11: 7. | B11: Горшков Владислав Васильевич | C11: осн | E11: 5 | F11: 5 | G11: 5 | H11: 5 | I11: 5 | J11: 5 | K11: 5 | L11: 5 | M11: 5 | N11: н/у | O11: 5 | P11: 5 | Q11: 5 | R11: 5 | T11: 5 | U11: н | V11: н | W11: 5 | BJ11: зачтено | BL11: =IFERROR(AVERAGE(C11:BK11),"Нет оценок") -> 5 | BM11: =COUNTIF(C11:BK11,"н/у") -> 1 | BN11: =COUNTIF(C11:BK11,"н") -> 2
A12: 8. | B12: Гришко Илья Алексеевич | C12: осн | E12: н/отр | F12: н/отр | G12: 5 | H12: 5 | I12: 3 | J12: 5 | K12: 5 | L12: 3 | M12: 4 | N12: 5 | O12: 5 | P12: 5 | Q12: 5 | R12: 5 | T12: 5 | U12: н | V12: н | W12: 3 | BJ12: зачтено | BL12: =IFERROR(AVERAGE(C12:BK12),"Нет оценок") -> 4.5 | BM12: =COUNTIF(C12:BK12,"н/у") -> 0 | BN12: =COUNTIF(C12:BK12,"н") -> 2
A13: 9. | B13: Катков Константин Александрович | C13: осн | E13: 5 | F13: 3 | G13: н/отр | H13: 3 | I13: н/отр | J13: н/отр | K13: н/отр | L13: 3 | M13: 5 | N13: 3 | O13: 5 | P13: н | Q13: н | R13: н | T13: н | U13: н | V13: н | W13: н | BJ13: неявка | BL13: =IFERROR(AVERAGE(C13:BK13),"Нет оценок") -> 3.8571429 | BM13: =COUNTIF(C13:BK13,"н/у") -> 0 | BN13: =COUNTIF(C13:BK13,"н") -> 7
A14: 10. | B14: Корнеев Андрей Александрович | C14: подг | E14: 5 | F14: 5 | G14: 5 | H14: н/отр | I14: 3 | J14: 5 | K14: 5 | L14: 5 | M14: 5 | O14: 5 | P14: 5 | Q14: 5 | T14: 5 | U14: 5 | V14: 5 | W14: 5 | BJ14: зачтено | BL14: =IFERROR(AVERAGE(C14:BK14),"Нет оценок") -> 4.8666667 | BM14: =COUNTIF(C14:BK14,"н/у") -> 0 | BN14: =COUNTIF(C14:BK14,"н") -> 0
A15: 11. | B15: Макаров Максим Алексеевич | C15: осн | E15: 5 | F15: н/у | G15: 5 | H15: 5 | I15: 5 | J15: 5 | K15: 5 | L15: 5 | M15: 5 | N15: 5 | O15: 5 | P15: 5 | Q15: 5 | T15: н | U15: 5 | V15: 5 | W15: 5 | BJ15: зачтено | BL15: =IFERROR(AVERAGE(C15:BK15),"Нет оценок") -> 5 | BM15: =COUNTIF(C15:BK15,"н/у") -> 1 | BN15: =COUNTIF(C15:BK15,"н") -> 1
A16: 13. | B16: Муллагалиев Вадим Радмилович | C16: осн | E16: 5 | F16: 5 | G16: 5 | H16: 5 | I16: 5 | J16: 5 | K16: 5 | L16: 5 | M16: 5 | N16: н/у | O16: 5 | P16: 5 | Q16: 5 | T16: 5 | U16: н | V16: н | W16: 5 | BJ16: зачтено | BL16: =IFERROR(AVERAGE(C16:BK16),"Нет оценок") -> 5 | BM16: =COUNTIF(C16:BK16,"н/у") -> 1 | BN16: =COUNTIF(C16:BK16,"н") -> 2
A17: 12. | B17: Натфуллин Камиль Данисович | C17: осн | D17: н/отр | E17: н/отр | F17: н/отр | G17: н/отр | H17: н/отр | I17: н/отр | J17: н/отр | K17: н/отр | L17: н/отр | M17: н/отр | N17: н/отр | O17: 3 | P17: 3 | Q17: 3 | T17: н | U17: н | V17: н | W17: н | BJ17: не зачтено | BL17: =IFERROR(AVERAGE(C17:BK17),"Нет оценок") -> 3 | BM17: =COUNTIF(C17:BK17,"н/у") -> 0 | BN17: =COUNTIF(C17:BK17,"н") -> 4
A18: 14. | B18: Носков Ярослав Евгеньевич | C18: подг | E18: 5 | F18: 5 | G18: 5 | H18: 5 | I18: н/отр | J18: н/отр | K18: 5 | L18: 3 | M18: 5 | N18: 5 | O18: 5 | P18: 5 | Q18: 5 | T18: 5 | U18: 5 | V18: 5 | W18: н | BJ18: зачтено | BL18: =IFERROR(AVERAGE(C18:BK18),"Нет оценок") -> 4.8571429 | BM18: =COUNTIF(C18:BK18,"н/у") -> 0 | BN18: =COUNTIF(C18:BK18,"н") -> 1
A19: 15. | B19: Осыка Владислав Сергеевич | C19: осн | E19: 5 | F19: 5 | G19: 5 | H19: 5 | I19: 5 | J19: 5 | K19: 5 | L19: н/отр | M19: 4 | N19: 5 | O19: 3 | P19: 5 | Q19: 5 | T19: 5 | U19: 5 | V19: 5 | W19: 5 | BJ19: зачтено | BL19: =IFERROR(AVERAGE(C19:BK19),"Нет оценок") -> 4.8125 | BM19: =COUNTIF(C19:BK19,"н/у") -> 0 | BN19: =COUNTIF(C19:BK19,"н") -> 0
A20: 16. | B20: Романов Михаил Васильевич | C20: осн | E20: 5 | F20: 5 | G20: 5 | H20: 5 | I20: 5 | J20: 5 | K20: 5 | L20: 5 | M20: 5 | N20: 5 | O20: 5 | T20: 5 | U20: н | V20: н | W20: 5 | BJ20: зачтено | BL20: =IFERROR(AVERAGE(C20:BK20),"Нет оценок") -> 5 | BM20: =COUNTIF(C20:BK20,"н/у") -> 0 | BN20: =COUNTIF(C20:BK20,"н") -> 2
A21: 17. | B21: Руфуллаев Ибрагим Фуадович | C21: осн | E21: 5 | F21: 5 | G21: н/отр | H21: 5 | I21: 3 | J21: 5 | K21: 4 | L21: 3 | M21: 5 | N21: 5 | O21: 5 | P21: 5 | Q21: 5 | T21: 5 | U21: 5 | V21: 5 | W21: 3 | BJ21: зачтено | BL21: =IFERROR(AVERAGE(C21:BK21),"Нет оценок") -> 4.5625 | BM21: =COUNTIF(C21:BK21,"н/у") -> 0 | BN21: =COUNTIF(C21:BK21,"н") -> 0
A22: 18. | B22: Сарычев Данила Андреевич | C22: осн | E22: 5 | F22: 5 | G22: н/отр | H22: н/отр | I22: 3 | J22: 5 | K22: 5 | L22: 5 | M22: 5 | O22: н/отр | P22: 5 | Q22: 5 | T22: 5 | U22: н | V22: н | W22: 5 | BJ22: зачтено | BL22: =IFERROR(AVERAGE(C22:BK22),"Нет оценок") -> 4.8181818 | BM22: =COUNTIF(C22:BK22,"н/у") -> 0 | BN22: =COUNTIF(C22:BK22,"н") -> 2
A23: 19. | B23: Сурков Кирилл Александрович | C23: спец | D23: н | E23: н | F23: н | G23: н | H23: н | I23: н | J23: н | K23: н | L23: н | M23: н | N23: н | O23: н | P23: н | Q23: н | T23: н | U23: 5 | V23: 5 | W23: н | BJ23: неявка | BL23: =IFERROR(AVERAGE(C23:BK23),"Нет оценок") -> 5 | BM23: =COUNTIF(C23:BK23,"н/у") -> 0 | BN23: =COUNTIF(C23:BK23,"н") -> 16
A24: 20. | B24: Усатов Тимофей Анатольевич | C24: осн | E24: 5 | F24: 5 | G24: 5 | H24: 5 | I24: 5 | J24: 5 | K24: 5 | L24: 5 | M24: 5 | N24: 5 | O24: 5 | T24: 5 | U24: 5 | V24: 5 | W24: 5 | BJ24: зачтено | BL24: =IFERROR(AVERAGE(C24:BK24),"Нет оценок") -> 5 | BM24: =COUNTIF(C24:BK24,"н/у") -> 0 | BN24: =COUNTIF(C24:BK24,"н") -> 0
A25: 21. | B25: Халитов Кирилл Родионович | C25: подг | D25: н/отр | E25: н/отр | F25: н | G25: н | H25: н | I25: н | J25: н | K25: н | L25: н | M25: 2 | N25: 3 | O25: н/у | P25: н | Q25: н | T25: н | U25: н | V25: н | W25: н | BJ25: неявка | BL25: =IFERROR(AVERAGE(C25:BK25),"Нет оценок") -> 2.5 | BM25: =COUNTIF(C25:BK25,"н/у") -> 1 | BN25: =COUNTIF(C25:BK25,"н") -> 13
A26: 21. | B26: Хорошилов Игорь Александрович | BJ26: зачтено | BL26: =IFERROR(AVERAGE(C26:BK26),"Нет оценок") -> Нет оценок | BM26: =COUNTIF(C26:BK26,"н/у") -> 0 | BN26: =COUNTIF(C26:BK26,"н") -> 0
A27: 22. | B27: Хрычев Мирон Евгеньевич | C27: осн | E27: 5 | F27: 5 | G27: 5 | H27: н/у | I27: н/у | J27: н/у | K27: н/у | L27: н/у | M27: н/у | N27: н/у | O27: н/у | P27: 5 | Q27: 5 | T27: н | U27: 5 | V27: 5 | W27: 5 | BJ27: зачтено | BL27: =IFERROR(AVERAGE(C27:BK27),"Нет оценок") -> 5 | BM27: =COUNTIF(C27:BK27,"н/у") -> 8 | BN27: =COUNTIF(C27:BK27,"н") -> 1
A28: 23. | B28: Цапов Илья Валерьевич | C28: подг | E28: 5 | F28: 5 | G28: н/у/ | H28: 5 | I28: 5 | J28: 5 | K28: н/отр | L28: н/отр | M28: 5 | N28: н/отр | O28: 5 | P28: 5 | Q28: 5 | T28: 5 | U28: 5 | V28: 5 | W28: 5 | BJ28: зачтено | BL28: =IFERROR(AVERAGE(C28:BK28),"Нет оценок") -> 5 | BM28: =COUNTIF(C28:BK28,"н/у") -> 0 | BN28: =COUNTIF(C28:BK28,"н") -> 0
A29: Дата | B29: Тема / ДЗ | BL29: =IFERROR(AVERAGE(BL5:BL28),"") -> 4.5934406 | BM29: =SUM(BM5:BM28) -> 12 | BN29: =SUM(BN5:BN28) -> 62
A30: 45903 | B30: Инструктаж по Ф.К.
A31: 45909 | B31: ОФП. (Геолог)
A32: 45923 | B32: ОФП+спортивные игры. (Геолог)
A33: 45945 | B33: ОФП+спортивные игры. (Геолог)
A34: 45954 | B34: ОФП+спортивные игры. (Геолог)
A35: 45959 | B35: ОФП+спортивные игры. (32 школа)
A36: 45959 | B36: ОФП+спортивные игры. (32 школа)
A37: 45961 | B37: ОФП+спортивные игры. (32 школа)
A38: 45966 | B38: ОФП+спортивные игры. (Геолог)
A39: 45973 | B39: ОФП+спортивные игры. (Геолог)
A40: 45982 | B40: ОФП+спортивные игры. (Геолог)
...

Sheet Элемент выш мат
A1: Наименование предмета | C1: Элементы высшей математики
A2: ФИО преподавателя | C2: Алпаева Валентина Викторовна
A3: ИСиП 24/2 | B3: Месяц | C3: Сентябрь | H3: Октябрь | K3: Ноябрь | R3: Декабрь | Y3: Январь | AG3: Февраль | AJ3: Апрель | BQ3: 4 сем | BS3: Пропуски
B4: Число | C4: 5 | D4: 9 | E4: 9 | F4: 11 | G4: 17 | H4: 7 | I4: 9 | J4: 14 | K4: 10 | L4: 10 | M4: 17 | N4: 18 | O4: 18 | P4: 20 | R4: 4 | S4: 5 | T4: 5 | U4: 8 | V4: 10 | W4: 16 | X4: 26 | Y4: 12 | Z4: 19 | AA4: 20 | AB4: 21 | AC4: 23 | AD4: 26 | AE4: 27 | AF4: 31 | AG4: 3 | AH4: 6 | AI4: 14 | AJ4: 6 | BQ4: Экз | BR4: Средний балл | BS4: Уваж. | BT4: Неуваж.
A5: 1. | B5: Адилбеков Бектур | C5: + | E5: 2 | F5: 5 | G5: 5 | J5: 2 | K5: оп | P5: 2 | Q5: 3 | R5: н | S5: н | T5: 3 | U5: н | V5: н | W5: 3 | X5: н | Y5: + | Z5: оп | AA5: 5 | AB5: н | AC5: н | AF5: оп | AG5: н | AH5: н | AI5: н/у | AJ5: н | BR5: =IFERROR(AVERAGE(C5:BQ5),"Нет оценок") -> 3.3333333 | BS5: =COUNTIF(C5:BQ5,"н/у") -> 1 | BT5: =COUNTIF(C5:BQ5,"н") -> 10
A6: 2. | B6: Ахметов Артём Рамилевич | E6: 5 | F6: 5 | G6: + | H6: 5 | I6: н | J6: н/у | K6: н/отр | N6: оп | P6: н | R6: н | T6: 2 | V6: н | W6: н | X6: 5 | Y6: + | Z6: 5 | AA6: н | AB6: н | AC6: н | AF6: н | AG6: 2 | AH6: н | AI6: оп | AJ6: 4 | BR6: =IFERROR(AVERAGE(C6:BQ6),"Нет оценок") -> 4.125 | BS6: =COUNTIF(C6:BQ6,"н/у") -> 1 | BT6: =COUNTIF(C6:BQ6,"н") -> 10
A7: 3. | B7: Бараников Владислав Михайлович | E7: 4 | F7: 5 | G7: оп | H7: 5 | J7: 3 | N7: 4 | P7: 5 | Q7: 4 | R7: 4 | T7: 2 | W7: 3 | X7: 5 | Y7: + | Z7: 2 | AA7: ? | AB7: н/отр | AC7: 5 | AG7: 2 | AI7: н | AJ7: y | BR7: =IFERROR(AVERAGE(C7:BQ7),"Нет оценок") -> 3.7857143 | BS7: =COUNTIF(C7:BQ7,"н/у") -> 0 | BT7: =COUNTIF(C7:BQ7,"н") -> 1
A8: 4. | B8: Борсук Артём Дмитриевич | E8: 4 | F8: н | G8: н | H8: 4 | J8: 2 | K8: оп | N8: оп | P8: 2 | Q8: 3 | R8: 4 | T8: 2 | W8: н | X8: н | Y8: ? | Z8: 3 | AA8: ? | AB8: 3 | AC8: 5 | AE8: н | AG8: 4 | AI8: н | AJ8: 4 | BR8: =IFERROR(AVERAGE(C8:BQ8),"Нет оценок") -> 3.3333333 | BS8: =COUNTIF(C8:BQ8,"н/у") -> 0 | BT8: =COUNTIF(C8:BQ8,"н") -> 6
A9: 5. | B9: Гильманов Ильназ Максимович | E9: 4 | G9: + | I9: оп | J9: н/отр | P9: 2 | Q9: 4 | R9: оп | T9: 2 | W9: 3 | X9: н | Y9: + | Z9: 3 | AA9: 4 | AB9: 4 | AC9: 2 | AD9: н | AE9: н | AG9: 4 | AJ9: 5 | BR9: =IFERROR(AVERAGE(C9:BQ9),"Нет оценок") -> 3.3636364 | BS9: =COUNTIF(C9:BQ9,"н/у") -> 0 | BT9: =COUNTIF(C9:BQ9,"н") -> 3
A10: 6. | B10: Говтва Илья Денисович | E10: 4 | G10: 5 | H10: 5 | J10: 3 | P10: 5 | Q10: 4 | R10: 4 | S10: 4 | T10: 2 | U10: 4 | V10: оп | W10: 3 | X10: 5 | Y10: + | Z10: 3 | AA10: 5 | AB10: 4 | AC10: 5 | AG10: 4 | AJ10: 4 | BR10: =IFERROR(AVERAGE(C10:BQ10),"Нет оценок") -> 4.0555556 | BS10: =COUNTIF(C10:BQ10,"н/у") -> 0 | BT10: =COUNTIF(C10:BQ10,"н") -> 0
A11: 7. | B11: Горшков Владислав Васильевич | C11: н | E11: 5 | F11: н | G11: + | J11: 2 | K11: н/отр | M11: н/у/отр | N11: н/у | O11: н/у | P11: н/у | R11: 4 | T11: 2 | W11: 3 | X11: 5 | Y11: + | Z11: 3 | AA11: ? | AB11: 4 | AC11: 5 | AF11: н/отр | AG11: 4 | AI11: оп | AJ11: 3 | BR11: =IFERROR(AVERAGE(C11:BQ11),"Нет оценок") -> 3.6363636 | BS11: =COUNTIF(C11:BQ11,"н/у") -> 3 | BT11: =COUNTIF(C11:BQ11,"н") -> 2
A12: 8. | B12: Гришко Илья Алексеевич | C12: н/отр | E12: 4 | F12: н/отр | G12: н/отр | I12: н | K12: оп/+ | P12: 2 | T12: 2 | U12: 5 | V12: 2 | W12: 3 | X12: 4 | Y12: + | Z12: 3 | AA12: н | AB12: н | AC12: 4 | AD12: н | AG12: 2 | AJ12: 3 | BR12: =IFERROR(AVERAGE(C12:BQ12),"Нет оценок") -> 3.0909091 | BS12: =COUNTIF(C12:BQ12,"н/у") -> 0 | BT12: =COUNTIF(C12:BQ12,"н") -> 4
A13: 9. | B13: Катков Константин Александрович | D13: н | E13: 2 | G13: 2 | H13: 3 | I13: оп | M13: 4 | N13: н | O13: н | P13: 3 | R13: н | T13: 2 | U13: н | V13: 2 | W13: 2 | X13: н | Y13: н | Z13: 2 | AA13: н | AB13: н | AC13: н | AD13: н | AE13: н | AF13: н | AG13: н | AI13: н | AJ13: 2 | BR13: =IFERROR(AVERAGE(C13:BQ13),"Нет оценок") -> 2.4 | BS13: =COUNTIF(C13:BQ13,"н/у") -> 0 | BT13: =COUNTIF(C13:BQ13,"н") -> 15
A14: 10. | B14: Корнеев Андрей Александрович | E14: 2 | J14: н/отр | P14: 2 | T14: 2 | W14: 2 | X14: 2 | Y14: + | Z14: 2 | AA14: ? | AB14: н | AC14: 3 | AD14: н | AG14: н | AJ14: 2 | BR14: =IFERROR(AVERAGE(C14:BQ14),"Нет оценок") -> 2.125 | BS14: =COUNTIF(C14:BQ14,"н/у") -> 0 | BT14: =COUNTIF(C14:BQ14,"н") -> 3
A15: 11. | B15: Макаров Максим Алексеевич | E15: 4 | I15: н/отр | J15: 3 | K15: 4 | P15: 4 | R15: 4 | T15: 2 | V15: 2 | W15: 2 | X15: 5 | Z15: 3 | AA15: ? | AB15: 5 | AC15: 3 | AG15: н | AJ15: 2 | BR15: =IFERROR(AVERAGE(C15:BQ15),"Нет оценок") -> 3.3076923 | BS15: =COUNTIF(C15:BQ15,"н/у") -> 0 | BT15: =COUNTIF(C15:BQ15,"н") -> 1
A16: 13. | B16: Муллагалиев Вадим Радмилович | C16: н | E16: 4 | G16: н | J16: 3 | K16: оп | N16: н/отр | O16: н | P16: н/у | R16: 4 | T16: 2 | V16: оп | W16: 3 | X16: н | Y16: ? | Z16: 3 | AA16: н | AB16: н | AC16: 2 | AF16: н | AG16: 2 | AH16: н | AI16: оп | AJ16: 4 | BR16: =IFERROR(AVERAGE(C16:BQ16),"Нет оценок") -> 3 | BS16: =COUNTIF(C16:BQ16,"н/у") -> 1 | BT16: =COUNTIF(C16:BQ16,"н") -> 8
A17: 12. | B17: Натфуллин Камиль Данисович | E17: 4 | F17: н | G17: оп | H17: н | I17: н | J17: н | K17: н | L17: н | M17: н/у | N17: оп | P17: н | R17: н | T17: 2 | U17: н | V17: н | W17: 2 | X17: н | Y17: н | Z17: 3 | AA17: ? | AB17: н | AC17: 5 | AE17: н | AF17: оп | AG17: 4 | AH17: оп | AI17: оп | AJ17: н | BR17: =IFERROR(AVERAGE(C17:BQ17),"Нет оценок") -> 3.3333333 | BS17: =COUNTIF(C17:BQ17,"н/у") -> 1 | BT17: =COUNTIF(C17:BQ17,"н") -> 15
A18: 14. | B18: Носков Ярослав Евгеньевич | E18: 4 | G18: + | H18: 3 | J18: 2 | P18: 5 | T18: 2 | U18: н | W18: 2 | X18: н | Y18: + | Z18: 2 | AA18: ? | AB18: н | AC18: н | AD18: н | AG18: н | AJ18: 4 | BR18: =IFERROR(AVERAGE(C18:BQ18),"Нет оценок") -> 3 | BS18: =COUNTIF(C18:BQ18,"н/у") -> 0 | BT18: =COUNTIF(C18:BQ18,"н") -> 6
A19: 15. | B19: Осыка Владислав Сергеевич | E19: 3 | F19: 4 | G19: оп | H19: н/отр | J19: н/отр | K19: оп | N19: оп | O19: 4 | P19: 2 | Q19: 3 | R19: 3 | T19: 2 | U19: + | V19: оп | W19: 3 | X19: 5 | Y19: н | Z19: 3 | AA19: 5 | AB19: 4 | AC19: 2 | AG19: 4 | AJ19: 3 | BR19: =IFERROR(AVERAGE(C19:BQ19),"Нет оценок") -> 3.3333333 | BS19: =COUNTIF(C19:BQ19,"н/у") -> 0 | BT19: =COUNTIF(C19:BQ19,"н") -> 1
A20: 16. | B20: Романов Михаил Васильевич | E20: 4 | G20: + | J20: 2 | P20: 4 | Q20: 3 | R20: 3 | T20: 2 | U20: 4 | V20: н | W20: 3 | X20: 4 | Y20: + | Z20: 2 | AA20: н | AB20: 3 | AC20: н | AG20: 4 | AJ20: 2 | BR20: =IFERROR(AVERAGE(C20:BQ20),"Нет оценок") -> 3.0769231 | BS20: =COUNTIF(C20:BQ20,"н/у") -> 0 | BT20: =COUNTIF(C20:BQ20,"н") -> 3
A21: 17. | B21: Руфуллаев Ибрагим Фуадович | E21: 3 | G21: 4 | H21: 4 | J21: 2 | K21: оп | N21: + | P21: 2 | Q21: 4 | R21: 4 | T21: 2 | U21: + | V21: оп | W21: 3 | X21: 5 | Y21: + | Z21: 3 | AA21: н | AB21: н | AC21: н | AD21: н | AE21: н | AF21: + | AG21: н | AJ21: 4 | BR21: =IFERROR(AVERAGE(C21:BQ21),"Нет оценок") -> 3.3333333 | BS21: =COUNTIF(C21:BQ21,"н/у") -> 0 | BT21: =COUNTIF(C21:BQ21,"н") -> 6
A22: 18. | B22: Сарычев Данила Андреевич | C22: н/отр | E22: 4 | G22: 4 | J22: 2 | M22: + | P22: 5 | Q22: 3 | T22: 3 | U22: 4 | W22: 3 | X22: 4 | Y22: + | Z22: 3 | AA22: 4 | AB22: 4 | AC22: 2 | AF22: н | AG22: 4 | AI22: н | AJ22: 3 | BR22: =IFERROR(AVERAGE(C22:BQ22),"Нет оценок") -> 3.4666667 | BS22: =COUNTIF(C22:BQ22,"н/у") -> 0 | BT22: =COUNTIF(C22:BQ22,"н") -> 2
A23: 19. | B23: Сурков Кирилл Александрович | D23: н | E23: 4 | F23: 5 | G23: н | H23: 4 | I23: оп | J23: 3 | K23: оп/+ | M23: оп | N23: н | P23: 4 | Q23: 4 | R23: 4 | T23: 3 | V23: н | W23: н | X23: н | Y23: н | Z23: н | AA23: н | AB23: 3 | AC23: 5 | AD23: н | AE23: н | AF23: 4 | AG23: 4 | AH23: н | AI23: н | AJ23: н | BR23: =IFERROR(AVERAGE(C23:BQ23),"Нет оценок") -> 3.9166667 | BS23: =COUNTIF(C23:BQ23,"н/у") -> 0 | BT23: =COUNTIF(C23:BQ23,"н") -> 14
A24: 20. | B24: Усатов Тимофей Анатольевич | E24: 3 | G24: 4 | J24: 3 | R24: 4 | T24: 2 | U24: + | V24: н/у/отр | W24: 3 | X24: 5 | Y24: + | Z24: 3 | AA24: 4 | AB24: 4 | AC24: 4 | AF24: 4 | AG24: 4 | AJ24: 4 | BR24: =IFERROR(AVERAGE(C24:BQ24),"Нет оценок") -> 3.6428571 | BS24: =COUNTIF(C24:BQ24,"н/у") -> 0 | BT24: =COUNTIF(C24:BQ24,"н") -> 0
A25: 21. | B25: Халитов Кирилл Родионович | D25: н | E25: 2 | G25: н | I25: н | J25: 2 | K25: н | L25: н | N25: н | O25: н | P25: 2 | Q25: 3 | R25: н/у | S25: н/у | T25: н/у | U25: н/у | V25: 2 | W25: н | X25: н | Y25: 2 | Z25: н | AA25: н | AB25: н | AC25: н | AE25: н | AF25: н | AG25: н | AI25: н | AJ25: н | BR25: =IFERROR(AVERAGE(C25:BQ25),"Нет оценок") -> 2.1666667 | BS25: =COUNTIF(C25:BQ25,"н/у") -> 4 | BT25: =COUNTIF(C25:BQ25,"н") -> 18
A26: 21. | B26: Хорошилов Игорь Александрович | BR26: =IFERROR(AVERAGE(C26:BQ26),"Нет оценок") -> Нет оценок | BS26: =COUNTIF(C26:BQ26,"н/у") -> 0 | BT26: =COUNTIF(C26:BQ26,"н") -> 0
A27: 22. | B27: Хрычев Мирон Евгеньевич | E27: 4 | G27: + | J27: 2 | N27: н | P27: 3 | R27: н | T27: 2 | U27: н | W27: 3 | X27: 5 | Y27: + | Z27: 2 | AA27: ? | AB27: н | AC27: 2 | AG27: н | AJ27: 2 | BR27: =IFERROR(AVERAGE(C27:BQ27),"Нет оценок") -> 2.7777778 | BS27: =COUNTIF(C27:BQ27,"н/у") -> 0 | BT27: =COUNTIF(C27:BQ27,"н") -> 5
A28: 23. | B28: Цапов Илья Валерьевич | D28: н | E28: 3 | I28: н/у | J28: н/у | K28: оп | M28: 4 | P28: 3 | Q28: 4 | R28: 3 | T28: 3 | V28: 4 | W28: н | X28: н | Y28: ? | Z28: 4 | AA28: 4 | AB28: н | AC28: н | AD28: н | AG28: н | AI28: н | AJ28: н | BR28: =IFERROR(AVERAGE(C28:BQ28),"Нет оценок") -> 3.5555556 | BS28: =COUNTIF(C28:BQ28,"н/у") -> 2 | BT28: =COUNTIF(C28:BQ28,"н") -> 9
A29: Дата | B29: Тема / ДЗ | BR29: =IFERROR(AVERAGE(BR5:BR28),"") -> 3.2678109 | BS29: =SUM(BS5:BS28) -> 13 | BT29: =SUM(BT5:BT28) -> 142
A30: 05\09 | B30: Матрицы и операции над ними (Л)
A31: 09\09 | B31: Матрицы и операции над ними (дистант)
A32: 09\09 | B32: Определитель матрицы, свойства (дистантт, практическая) (Л) | O32: л | P32: п
A33: 11\09 | B33: Определитель матрицы, минор, алгебраическое дополнение
A34: 17\09 | B34: Обратная матрица
A35: 07\10 | B35: Решение СЛАУ
A36: 09\10 | B36: Матрицы и операции над ними (подготовка)
A37: 14\10 | B37: Матрицы и операции над ними (с/р)
A38: 10\11 | B38: Комплексные числа (Л)
A39: 10\11 | B39: Комплексные числа (ПЗ)
A40: 17\11 | B40: Тригонометрическая форма комплексного числа
...

Sheet арх.ап.средств
A1: Наименование предмета | C1: Архитектура аппаратных средств
A2: ФИО преподавателя | C2: Клейменов Степан Владимирович
A3: ИСиП 24/2 | B3: Дата | C3: 13.09. | F3: 45920 | G3: 45927 | J3: 45934 | M3: 18.10.25 | P3: 45958 | Q3: 45960 | T3: 45976 | U3: 45983 | W3: 46018 | AP3: 3 сем | AR3: Пропуски
B4: Темы | C4: согл.тем | F4: проц | G4: мат.плата | H4: сис.охлаж | I4: Опер.пам | J4: ssd | K4: ЖД | L4: видео | M4: блок пит | N4: корпус | O4: кулер | P4: монитор | Q4: коллоквиум | T4: сам раб | U4: сам раб | W4: Диф зачет | AP4: ДЗ | AQ4: Средний балл | AR4: Уваж. | AS4: Неуваж.
A5: 1. | B5: Адилбеков Бектур | E5: 5 | M5: н | N5: н | O5: н | Q5: н | R5: н | S5: н | T5: н | U5: н | V5: н | W5: н | X5: н | AQ5: =IFERROR(AVERAGE(C5:AP5),"Нет оценок") -> 5 | AR5: =COUNTIF(C5:AP5,"н/у") -> 0 | AS5: =COUNTIF(C5:AP5,"н") -> 11
A6: 2. | B6: Ахметов Артём Рамилевич | E6: 5 | F6: 5 | G6: 3 | H6: 4 | I6: 5 | J6: 5 | K6: 4 | L6: 3 | M6: 4 | N6: 4 | O6: 5 | P6: 5 | R6: 4 | S6: 4 | X6: 4 | AQ6: =IFERROR(AVERAGE(C6:AP6),"Нет оценок") -> 4.2666667 | AR6: =COUNTIF(C6:AP6,"н/у") -> 0 | AS6: =COUNTIF(C6:AP6,"н") -> 0
A7: 3. | B7: Бараников Владислав Михайлович | E7: 5 | F7: 5 | G7: 5 | H7: 4 | I7: 5 | J7: 5 | K7: 5 | L7: 4 | M7: 4 | N7: 4 | O7: 4 | P7: 5 | R7: 4 | S7: 4 | X7: 4 | AQ7: =IFERROR(AVERAGE(C7:AP7),"Нет оценок") -> 4.4666667 | AR7: =COUNTIF(C7:AP7,"н/у") -> 0 | AS7: =COUNTIF(C7:AP7,"н") -> 0
A8: 4. | B8: Борсук Артём Дмитриевич | E8: 5 | F8: 4 | G8: 4 | H8: 4 | I8: 5 | J8: 4 | K8: 5 | L8: 5 | M8: 5 | N8: 5 | O8: 5 | P8: 5 | R8: 4 | S8: 4 | X8: 5 | AQ8: =IFERROR(AVERAGE(C8:AP8),"Нет оценок") -> 4.6 | AR8: =COUNTIF(C8:AP8,"н/у") -> 0 | AS8: =COUNTIF(C8:AP8,"н") -> 0
A9: 5. | B9: Гильманов Ильназ Максимович | E9: 5 | F9: 3 | G9: 3 | H9: 3 | I9: 3 | J9: 3 | K9: 3 | L9: 3 | M9: 3 | N9: 3 | O9: 3 | P9: 3 | R9: 3 | S9: 3 | X9: 3 | AQ9: =IFERROR(AVERAGE(C9:AP9),"Нет оценок") -> 3.1333333 | AR9: =COUNTIF(C9:AP9,"н/у") -> 0 | AS9: =COUNTIF(C9:AP9,"н") -> 0
A10: 6. | B10: Говтва Илья Денисович | E10: 5 | F10: 5 | G10: 5 | H10: 5 | I10: 5 | J10: 5 | K10: 5 | L10: 5 | M10: 5 | N10: 5 | O10: 5 | P10: 5 | R10: 5 | S10: 5 | X10: 5 | AQ10: =IFERROR(AVERAGE(C10:AP10),"Нет оценок") -> 5 | AR10: =COUNTIF(C10:AP10,"н/у") -> 0 | AS10: =COUNTIF(C10:AP10,"н") -> 0
A11: 7. | B11: Горшков Владислав Васильевич | E11: 5 | F11: 3 | G11: н/у | H11: н/у | I11: н/у | J11: н/у | K11: н/у | L11: н/у | M11: 3 | N11: 3 | O11: 3 | P11: 3 | R11: 3 | S11: 3 | T11: н/у | U11: н/у | V11: н/у | X11: 3 | AQ11: =IFERROR(AVERAGE(C11:AP11),"Нет оценок") -> 3.2222222 | AR11: =COUNTIF(C11:AP11,"н/у") -> 9 | AS11: =COUNTIF(C11:AP11,"н") -> 0
A12: 8. | B12: Гришко Илья Алексеевич | E12: 5 | F12: 5 | G12: 5 | H12: 5 | I12: 5 | J12: 4 | K12: 4 | L12: 5 | M12: 5 | N12: 5 | O12: 5 | P12: 5 | R12: 4 | S12: 4 | X12: 5 | AQ12: =IFERROR(AVERAGE(C12:AP12),"Нет оценок") -> 4.7333333 | AR12: =COUNTIF(C12:AP12,"н/у") -> 0 | AS12: =COUNTIF(C12:AP12,"н") -> 0
A13: 9. | B13: Катков Константин Александрович | E13: 5 | F13: 3 | G13: 3 | H13: 3 | I13: 3 | J13: 3 | K13: 3 | L13: 3 | M13: 3 | N13: 3 | O13: 3 | P13: 3 | R13: 3 | S13: 3 | X13: 3 | AQ13: =IFERROR(AVERAGE(C13:AP13),"Нет оценок") -> 3.1333333 | AR13: =COUNTIF(C13:AP13,"н/у") -> 0 | AS13: =COUNTIF(C13:AP13,"н") -> 0
A14: 10. | B14: Корнеев Андрей Александрович | E14: 5 | F14: 3 | G14: 3 | H14: 3 | I14: 3 | J14: 3 | K14: 3 | L14: 3 | M14: 3 | N14: 3 | O14: 3 | P14: 3 | R14: 3 | S14: 3 | X14: 3 | AQ14: =IFERROR(AVERAGE(C14:AP14),"Нет оценок") -> 3.1333333 | AR14: =COUNTIF(C14:AP14,"н/у") -> 0 | AS14: =COUNTIF(C14:AP14,"н") -> 0
A15: 11. | B15: Макаров Максим Алексеевич | E15: 5 | F15: 4 | G15: 5 | H15: 3 | I15: 4 | J15: 5 | K15: 5 | L15: 5 | M15: 4 | N15: 4 | O15: 4 | P15: 5 | R15: 4 | S15: 4 | X15: 4 | AQ15: =IFERROR(AVERAGE(C15:AP15),"Нет оценок") -> 4.3333333 | AR15: =COUNTIF(C15:AP15,"н/у") -> 0 | AS15: =COUNTIF(C15:AP15,"н") -> 0
A16: 12. | B16: Муллагалиев Вадим Радмилович | E16: 5 | F16: 4 | G16: 4 | H16: 4 | I16: 4 | J16: 4 | K16: 4 | L16: 4 | M16: 4 | N16: 4 | O16: 4 | P16: 4 | R16: 3 | S16: 3 | X16: 4 | AQ16: =IFERROR(AVERAGE(C16:AP16),"Нет оценок") -> 3.9333333 | AR16: =COUNTIF(C16:AP16,"н/у") -> 0 | AS16: =COUNTIF(C16:AP16,"н") -> 0
A17: 13. | B17: Натфуллин Камиль Данисович | E17: 3 | F17: 3 | G17: 3 | H17: 3 | I17: 3 | J17: 3 | K17: 3 | L17: 3 | M17: 3 | N17: 3 | O17: 3 | P17: 3 | R17: 3 | S17: 3 | X17: 3 | AQ17: =IFERROR(AVERAGE(C17:AP17),"Нет оценок") -> 3 | AR17: =COUNTIF(C17:AP17,"н/у") -> 0 | AS17: =COUNTIF(C17:AP17,"н") -> 0
A18: 14. | B18: Носков Ярослав Евгеньевич | E18: 5 | Q18: н | R18: н | S18: н | T18: н/у | W18: н | X18: н | AQ18: =IFERROR(AVERAGE(C18:AP18),"Нет оценок") -> 5 | AR18: =COUNTIF(C18:AP18,"н/у") -> 1 | AS18: =COUNTIF(C18:AP18,"н") -> 5
A19: 15. | B19: Осыка Владислав Сергеевич | E19: 5 | F19: 5 | G19: 5 | H19: 5 | I19: 4 | J19: 4 | K19: 5 | L19: 5 | M19: 4 | N19: 5 | O19: 5 | P19: 5 | R19: 4 | S19: 3 | X19: 4 | AQ19: =IFERROR(AVERAGE(C19:AP19),"Нет оценок") -> 4.5333333 | AR19: =COUNTIF(C19:AP19,"н/у") -> 0 | AS19: =COUNTIF(C19:AP19,"н") -> 0
A20: 16. | B20: Романов Михаил Васильевич | E20: 5 | F20: 3 | G20: 3 | H20: 3 | I20: 3 | J20: 3 | K20: 3 | L20: 3 | M20: 3 | N20: 3 | O20: 3 | P20: 3 | R20: 3 | S20: 3 | X20: 3 | AQ20: =IFERROR(AVERAGE(C20:AP20),"Нет оценок") -> 3.1333333 | AR20: =COUNTIF(C20:AP20,"н/у") -> 0 | AS20: =COUNTIF(C20:AP20,"н") -> 0
A21: 18. | B21: Руфуллаев Ибрагим Фуадович | E21: 5 | F21: 5 | G21: 5 | H21: 4 | I21: 4 | J21: 5 | K21: 5 | L21: 5 | M21: 5 | N21: 4 | O21: 4 | P21: 5 | R21: 5 | S21: 5 | X21: 5 | AQ21: =IFERROR(AVERAGE(U21:AP21),"Нет оценок") -> 5 | AR21: =COUNTIF(U21:AP21,"н/у") -> 0 | AS21: =COUNTIF(U21:AP21,"н") -> 0
A22: 19. | B22: Сурков Кирилл Александрович | E22: 5 | F22: 4 | G22: 5 | H22: 4 | I22: 5 | J22: 5 | K22: 4 | L22: 3 | M22: 5 | N22: 4 | O22: 4 | P22: 5 | R22: 3 | S22: 4 | X22: 4 | AQ22: =IFERROR(AVERAGE(C22:AP22),"Нет оценок") -> 4.2666667 | AR22: =COUNTIF(C22:AP22,"н/у") -> 0 | AS22: =COUNTIF(C22:AP22,"н") -> 0
A23: 20. | B23: Усатов Тимофей Анатольевич | E23: 5 | F23: 5 | G23: 5 | H23: 5 | I23: 5 | J23: 5 | K23: 4 | L23: 4 | M23: 5 | N23: 5 | O23: 5 | P23: 5 | R23: 4 | S23: 4 | X23: 5 | AQ23: =IFERROR(AVERAGE(C23:AP23),"Нет оценок") -> 4.7333333 | AR23: =COUNTIF(C23:AP23,"н/у") -> 0 | AS23: =COUNTIF(C23:AP23,"н") -> 0
A24: 21. | B24: Халитов Кирилл Родионович | E24: 5 | F24: 5 | G24: 4 | H24: 5 | I24: 5 | J24: 4 | K24: 5 | L24: 5 | M24: 5 | N24: 5 | O24: 5 | P24: 5 | R24: 5 | S24: 5 | X24: 5 | AQ24: =IFERROR(AVERAGE(C24:AP24),"Нет оценок") -> 4.8666667 | AR24: =COUNTIF(C24:AP24,"н/у") -> 0 | AS24: =COUNTIF(C24:AP24,"н") -> 0
A25: 22. | B25: Хорошилов Игорь Александрович | AQ25: =IFERROR(AVERAGE(C25:AP25),"Нет оценок") -> Нет оценок | AR25: =COUNTIF(C25:AP25,"н/у") -> 0 | AS25: =COUNTIF(C25:AP25,"н") -> 0
A26: 23. | B26: Хрычев Мирон Евгеньевич | E26: 5 | F26: 3 | G26: 3 | H26: 3 | I26: 3 | J26: 3 | K26: 3 | L26: 3 | M26: 3 | N26: 3 | O26: 3 | P26: 3 | Q26: н/у | R26: 3 | S26: 3 | X26: 3 | AQ26: =IFERROR(AVERAGE(C26:AP26),"Нет оценок") -> 3.1333333 | AR26: =COUNTIF(C26:AP26,"н/у") -> 1 | AS26: =COUNTIF(C26:AP26,"н") -> 0
